2024-01-19 11:13:32,807 - MainThread - MainProcess - django.utils.autoreload - INFO - Watching for file changes with StatReloader
2024-01-19 11:13:54,311 - MainThread - MainProcess - django.utils.autoreload - INFO - Watching for file changes with StatReloader
2024-01-19 11:14:30,012 - MainThread - MainProcess - django.utils.autoreload - INFO - Watching for file changes with StatReloader
2024-01-19 11:14:39,995 - Thread-1 (process_request_thread) - MainProcess - django.server - INFO - "PUT /api/v1.0/tasks/13/ HTTP/1.1" 200 132
2024-01-19 11:15:49,873 - MainThread - MainProcess - django.utils.autoreload - INFO - /home/dverdun/Documentos/Programacion_python/Prueba_tecnica/ToDo-Challenge-invera/todo-challenge/Core/TaskApp/viewsets.py changed, reloading.
2024-01-19 11:15:50,494 - MainThread - MainProcess - django.utils.autoreload - INFO - Watching for file changes with StatReloader
2024-01-19 11:16:23,120 - Thread-1 (process_request_thread) - MainProcess - django.server - INFO - "POST /api/v1.0/tasks/ HTTP/1.1" 201 132
2024-01-19 11:16:52,951 - Thread-1 (process_request_thread) - MainProcess - django.server - INFO - "DELETE /api/v1.0/tasks/14/ HTTP/1.1" 204 0
2024-01-19 11:17:02,206 - Thread-1 (process_request_thread) - MainProcess - django.server - INFO - "GET /api/v1.0/tasks/ HTTP/1.1" 200 1723
2024-01-19 11:17:29,809 - Thread-1 (process_request_thread) - MainProcess - django.server - INFO - "DELETE /api/v1.0/tasks/13/ HTTP/1.1" 204 0
2024-01-19 11:17:44,314 - Thread-1 (process_request_thread) - MainProcess - django.server - INFO - "GET /api/v1.0/tasks/ HTTP/1.1" 200 1590
2024-01-19 17:16:31,860 - MainThread - MainProcess - django.request - WARNING - Not Found: /api/tasks/
2024-01-19 17:16:31,864 - MainThread - MainProcess - django.request - WARNING - Not Found: /api/tasks/1/
2024-01-19 17:16:31,868 - MainThread - MainProcess - django.request - WARNING - Not Found: /api/tasks/
2024-01-19 17:16:31,873 - MainThread - MainProcess - django.request - WARNING - Not Found: /api/tasks/1/
2024-01-19 17:18:54,012 - MainThread - MainProcess - django.request - WARNING - Not Found: /api/tasks/
2024-01-19 17:18:54,015 - MainThread - MainProcess - django.request - WARNING - Not Found: /api/tasks/1/
2024-01-19 17:18:54,018 - MainThread - MainProcess - django.request - WARNING - Not Found: /api/tasks/
2024-01-19 17:23:23,676 - MainThread - MainProcess - django.utils.autoreload - INFO - Watching for file changes with StatReloader
2024-01-19 17:24:10,580 - MainThread - MainProcess - django.request - WARNING - Not Found: /api/tasks/
2024-01-19 17:24:10,585 - MainThread - MainProcess - django.request - WARNING - Not Found: /api/tasks/1/
2024-01-19 17:24:10,588 - MainThread - MainProcess - django.request - WARNING - Not Found: /api/tasks/
2024-01-19 17:28:50,156 - MainThread - MainProcess - django.utils.autoreload - INFO - Watching for file changes with StatReloader
2024-01-19 17:28:59,082 - MainThread - MainProcess - django.request - WARNING - Not Found: /api/tasks/
2024-01-19 17:28:59,085 - MainThread - MainProcess - django.request - WARNING - Not Found: /api/tasks/1/
2024-01-19 17:28:59,090 - MainThread - MainProcess - django.request - WARNING - Not Found: /api/tasks/
2024-01-19 17:28:59,094 - MainThread - MainProcess - django.request - WARNING - Not Found: /api/tasks/1/
2024-01-20 10:27:54,228 - MainThread - MainProcess - django.utils.autoreload - INFO - Watching for file changes with StatReloader
2024-01-20 10:28:00,925 - Thread-1 (process_request_thread) - MainProcess - django.request - WARNING - Not Found: /api/v1.0/auth/login/
2024-01-20 10:28:00,926 - Thread-1 (process_request_thread) - MainProcess - django.server - WARNING - "POST /api/v1.0/auth/login/ HTTP/1.1" 404 0
2024-01-20 10:33:30,775 - MainThread - MainProcess - django.utils.autoreload - INFO - /home/dverdun/Documentos/Programacion_python/Prueba_tecnica/ToDo-Challenge-invera/todo-challenge/Core/Core/urls.py changed, reloading.
2024-01-20 10:33:31,390 - MainThread - MainProcess - django.utils.autoreload - INFO - Watching for file changes with StatReloader
2024-01-20 10:33:38,587 - Thread-1 (process_request_thread) - MainProcess - django.request - WARNING - Not Found: /api/v1.0/auth/login/
2024-01-20 10:33:38,588 - Thread-1 (process_request_thread) - MainProcess - django.server - WARNING - "POST /api/v1.0/auth/login/ HTTP/1.1" 404 0
2024-01-20 10:34:03,978 - MainThread - MainProcess - django.utils.autoreload - INFO - /home/dverdun/Documentos/Programacion_python/Prueba_tecnica/ToDo-Challenge-invera/todo-challenge/Core/Core/urls.py changed, reloading.
2024-01-20 10:34:04,545 - MainThread - MainProcess - django.utils.autoreload - INFO - Watching for file changes with StatReloader
2024-01-20 10:34:07,276 - Thread-1 (process_request_thread) - MainProcess - django.request - WARNING - Not Found: /api/v1.0/auth/login/
2024-01-20 10:34:07,277 - Thread-1 (process_request_thread) - MainProcess - django.server - WARNING - "POST /api/v1.0/auth/login/ HTTP/1.1" 404 0
2024-01-20 10:36:13,707 - Thread-2 (process_request_thread) - MainProcess - django.request - WARNING - Not Found: /api/v1.0/auth/login/
2024-01-20 10:36:13,708 - Thread-2 (process_request_thread) - MainProcess - django.server - WARNING - "POST /api/v1.0/auth/login/ HTTP/1.1" 404 0
2024-01-20 10:43:52,515 - MainThread - MainProcess - django.utils.autoreload - INFO - /home/dverdun/Documentos/Programacion_python/Prueba_tecnica/ToDo-Challenge-invera/todo-challenge/Core/authentication/urls.py changed, reloading.
2024-01-20 10:43:53,025 - MainThread - MainProcess - django.utils.autoreload - INFO - Watching for file changes with StatReloader
2024-01-20 10:44:58,272 - MainThread - MainProcess - django.utils.autoreload - INFO - Watching for file changes with StatReloader
2024-01-20 10:48:35,177 - MainThread - MainProcess - django.utils.autoreload - INFO - Watching for file changes with StatReloader
2024-01-20 10:50:24,475 - MainThread - MainProcess - django.utils.autoreload - INFO - Watching for file changes with StatReloader
2024-01-20 10:52:11,538 - MainThread - MainProcess - django.utils.autoreload - INFO - Watching for file changes with StatReloader
2024-01-20 10:54:13,862 - MainThread - MainProcess - django.utils.autoreload - INFO - Watching for file changes with StatReloader
2024-01-20 11:00:35,354 - MainThread - MainProcess - django.utils.autoreload - INFO - Watching for file changes with StatReloader
2024-01-20 11:03:28,424 - MainThread - MainProcess - django.utils.autoreload - INFO - Watching for file changes with StatReloader
2024-01-20 11:07:21,527 - MainThread - MainProcess - django.utils.autoreload - INFO - Watching for file changes with StatReloader
2024-01-20 11:08:38,540 - Thread-1 (process_request_thread) - MainProcess - django.request - WARNING - Not Found: /api/v1.0/auth/login/
2024-01-20 11:08:38,540 - Thread-1 (process_request_thread) - MainProcess - django.server - WARNING - "POST /api/v1.0/auth/login/ HTTP/1.1" 404 0
2024-01-20 11:14:12,176 - Thread-1 (process_request_thread) - MainProcess - django.request - WARNING - Not Found: /api/v1.0/auth/login/
2024-01-20 11:14:12,176 - Thread-1 (process_request_thread) - MainProcess - django.server - WARNING - "POST /api/v1.0/auth/login/ HTTP/1.1" 404 0
2024-01-20 11:18:10,076 - MainThread - MainProcess - django.utils.autoreload - INFO - /home/dverdun/Documentos/Programacion_python/Prueba_tecnica/ToDo-Challenge-invera/todo-challenge/Core/Core/urls.py changed, reloading.
2024-01-20 11:18:10,622 - MainThread - MainProcess - django.utils.autoreload - INFO - Watching for file changes with StatReloader
2024-01-20 11:18:30,425 - Thread-1 (process_request_thread) - MainProcess - django.request - WARNING - Not Found: /api/v1.0/auth/login/
2024-01-20 11:18:30,425 - Thread-1 (process_request_thread) - MainProcess - django.server - WARNING - "POST /api/v1.0/auth/login/ HTTP/1.1" 404 0
2024-01-20 11:28:55,188 - MainThread - MainProcess - django.utils.autoreload - INFO - /home/dverdun/Documentos/Programacion_python/Prueba_tecnica/ToDo-Challenge-invera/todo-challenge/Core/authentication/urls.py changed, reloading.
2024-01-20 11:28:55,756 - MainThread - MainProcess - django.utils.autoreload - INFO - Watching for file changes with StatReloader
2024-01-20 11:29:32,236 - MainThread - MainProcess - django.utils.autoreload - INFO - /home/dverdun/Documentos/Programacion_python/Prueba_tecnica/ToDo-Challenge-invera/todo-challenge/Core/Core/urls.py changed, reloading.
2024-01-20 11:29:32,796 - MainThread - MainProcess - django.utils.autoreload - INFO - Watching for file changes with StatReloader
2024-01-20 11:30:29,478 - Thread-1 (process_request_thread) - MainProcess - django.request - WARNING - Not Found: /api/v1.0/auth/login/
2024-01-20 11:30:29,479 - Thread-1 (process_request_thread) - MainProcess - django.server - WARNING - "POST /api/v1.0/auth/login/ HTTP/1.1" 404 0
2024-01-20 11:30:56,714 - Thread-2 (process_request_thread) - MainProcess - django.request - WARNING - Method Not Allowed: /api/v1.0/auth/login/
2024-01-20 11:30:56,715 - Thread-2 (process_request_thread) - MainProcess - django.server - WARNING - "GET /api/v1.0/auth/login/ HTTP/1.1" 405 5613
2024-01-20 11:30:56,751 - Thread-3 (process_request_thread) - MainProcess - django.server - INFO - "GET /static/rest_framework/css/bootstrap-tweaks.css HTTP/1.1" 304 0
2024-01-20 11:30:56,753 - Thread-4 (process_request_thread) - MainProcess - django.server - INFO - "GET /static/rest_framework/css/prettify.css HTTP/1.1" 304 0
2024-01-20 11:30:56,756 - Thread-3 (process_request_thread) - MainProcess - django.server - INFO - "GET /static/rest_framework/js/csrf.js HTTP/1.1" 304 0
2024-01-20 11:30:56,757 - Thread-2 (process_request_thread) - MainProcess - django.server - INFO - "GET /static/rest_framework/css/bootstrap.min.css HTTP/1.1" 304 0
2024-01-20 11:30:56,758 - Thread-5 (process_request_thread) - MainProcess - django.server - INFO - "GET /static/rest_framework/css/default.css HTTP/1.1" 304 0
2024-01-20 11:30:56,760 - Thread-4 (process_request_thread) - MainProcess - django.server - INFO - "GET /static/rest_framework/js/bootstrap.min.js HTTP/1.1" 304 0
2024-01-20 11:30:56,764 - Thread-5 (process_request_thread) - MainProcess - django.server - INFO - "GET /static/rest_framework/js/prettify-min.js HTTP/1.1" 304 0
2024-01-20 11:30:56,765 - Thread-6 (process_request_thread) - MainProcess - django.server - INFO - "GET /static/rest_framework/js/jquery-3.5.1.min.js HTTP/1.1" 304 0
2024-01-20 11:30:56,767 - Thread-7 (process_request_thread) - MainProcess - django.server - INFO - "GET /static/rest_framework/js/ajax-form.js HTTP/1.1" 304 0
2024-01-20 11:30:56,771 - Thread-6 (process_request_thread) - MainProcess - django.server - INFO - "GET /static/rest_framework/js/default.js HTTP/1.1" 304 0
2024-01-20 11:30:56,825 - Thread-6 (process_request_thread) - MainProcess - django.server - INFO - "GET /static/rest_framework/img/grid.png HTTP/1.1" 304 0
2024-01-20 11:31:32,279 - Thread-6 (process_request_thread) - MainProcess - django.request - WARNING - Not Found: /api/v1.0/auth/login/
2024-01-20 11:31:32,280 - Thread-6 (process_request_thread) - MainProcess - django.server - WARNING - "POST /api/v1.0/auth/login/ HTTP/1.1" 404 5528
2024-01-20 11:34:29,407 - Thread-1 (process_request_thread) - MainProcess - django.request - WARNING - Not Found: /api/v1.0/login/
2024-01-20 11:34:29,407 - Thread-1 (process_request_thread) - MainProcess - django.server - WARNING - "POST /api/v1.0/login/ HTTP/1.1" 404 2872
2024-01-20 11:34:57,154 - Thread-6 (process_request_thread) - MainProcess - django.request - WARNING - Not Found: /api/v1.0/login/
2024-01-20 11:34:57,154 - Thread-6 (process_request_thread) - MainProcess - django.server - WARNING - "GET /api/v1.0/login/ HTTP/1.1" 404 2871
2024-01-20 11:35:29,616 - Thread-6 (process_request_thread) - MainProcess - django.request - WARNING - Method Not Allowed: /api/v1.0/auth/login/
2024-01-20 11:35:29,617 - Thread-6 (process_request_thread) - MainProcess - django.server - WARNING - "GET /api/v1.0/auth/login/ HTTP/1.1" 405 5613
2024-01-20 11:35:57,835 - Thread-1 (process_request_thread) - MainProcess - django.request - WARNING - Not Found: /api/v1.0/auth/login/
2024-01-20 11:35:57,836 - Thread-1 (process_request_thread) - MainProcess - django.server - WARNING - "POST /api/v1.0/auth/login/ HTTP/1.1" 404 0
2024-01-20 11:36:02,701 - Thread-1 (process_request_thread) - MainProcess - django.request - ERROR - Internal Server Error: /api/v1.0/auth/login
Traceback (most recent call last):
  File "/home/dverdun/.local/lib/python3.10/site-packages/django/core/handlers/exception.py", line 55, in inner
    response = get_response(request)
  File "/home/dverdun/.local/lib/python3.10/site-packages/django/utils/deprecation.py", line 136, in __call__
    response = self.process_response(request, response)
  File "/home/dverdun/.local/lib/python3.10/site-packages/django/middleware/common.py", line 108, in process_response
    return self.response_redirect_class(self.get_full_path_with_slash(request))
  File "/home/dverdun/.local/lib/python3.10/site-packages/django/middleware/common.py", line 87, in get_full_path_with_slash
    raise RuntimeError(
RuntimeError: You called this URL via POST, but the URL doesn't end in a slash and you have APPEND_SLASH set. Django can't redirect to the slash URL while maintaining POST data. Change your form to point to 127.0.0.1:8000/api/v1.0/auth/login/ (note the trailing slash), or set APPEND_SLASH=False in your Django settings.
2024-01-20 11:36:02,701 - Thread-1 (process_request_thread) - MainProcess - django.server - ERROR - "POST /api/v1.0/auth/login HTTP/1.1" 500 68450
2024-01-20 11:36:13,630 - Thread-8 (process_request_thread) - MainProcess - django.request - WARNING - Not Found: /api/v1.0/auth/login/
2024-01-20 11:36:13,630 - Thread-8 (process_request_thread) - MainProcess - django.server - WARNING - "POST /api/v1.0/auth/login/ HTTP/1.1" 404 0
2024-01-20 11:36:42,538 - Thread-6 (process_request_thread) - MainProcess - django.server - INFO - "GET /admin/LogsApp/logentry/ HTTP/1.1" 302 0
2024-01-20 11:36:42,583 - Thread-6 (process_request_thread) - MainProcess - django.server - INFO - "GET /admin/login/?next=/admin/LogsApp/logentry/ HTTP/1.1" 200 4189
2024-01-20 11:36:42,651 - Thread-6 (process_request_thread) - MainProcess - django.server - INFO - "GET /static/admin/css/base.css HTTP/1.1" 304 0
2024-01-20 11:36:42,658 - Thread-9 (process_request_thread) - MainProcess - django.server - INFO - "GET /static/admin/css/dark_mode.css HTTP/1.1" 304 0
2024-01-20 11:36:42,664 - Thread-10 (process_request_thread) - MainProcess - django.server - INFO - "GET /static/admin/css/nav_sidebar.css HTTP/1.1" 304 0
2024-01-20 11:36:42,665 - Thread-12 (process_request_thread) - MainProcess - django.server - INFO - "GET /static/admin/css/responsive.css HTTP/1.1" 304 0
2024-01-20 11:36:42,666 - Thread-11 (process_request_thread) - MainProcess - django.server - INFO - "GET /static/admin/css/login.css HTTP/1.1" 304 0
2024-01-20 11:36:42,685 - Thread-12 (process_request_thread) - MainProcess - django.server - INFO - "GET /static/admin/js/theme.js HTTP/1.1" 304 0
2024-01-20 11:36:42,686 - Thread-11 (process_request_thread) - MainProcess - django.server - INFO - "GET /static/admin/js/nav_sidebar.js HTTP/1.1" 304 0
2024-01-20 11:45:44,675 - MainThread - MainProcess - django.utils.autoreload - INFO - /home/dverdun/Documentos/Programacion_python/Prueba_tecnica/ToDo-Challenge-invera/todo-challenge/Core/Core/settings.py changed, reloading.
2024-01-20 11:45:45,579 - MainThread - MainProcess - django.utils.autoreload - INFO - Watching for file changes with StatReloader
2024-01-20 11:45:52,257 - Thread-1 (process_request_thread) - MainProcess - django.request - WARNING - Not Found: /api/v1.0/auth/login/
2024-01-20 11:45:52,258 - Thread-1 (process_request_thread) - MainProcess - django.server - WARNING - "POST /api/v1.0/auth/login/ HTTP/1.1" 404 0
2024-01-20 12:04:38,810 - Thread-1 (process_request_thread) - MainProcess - django.request - WARNING - Not Found: /api/v1.0/auth/login/
2024-01-20 12:04:38,810 - Thread-1 (process_request_thread) - MainProcess - django.server - WARNING - "POST /api/v1.0/auth/login/ HTTP/1.1" 404 0
2024-01-20 22:43:35,167 - MainThread - MainProcess - django.utils.autoreload - INFO - Watching for file changes with StatReloader
2024-01-20 23:11:50,535 - MainThread - MainProcess - django.utils.autoreload - INFO - Watching for file changes with StatReloader
2024-01-20 23:11:54,335 - Thread-1 (process_request_thread) - MainProcess - django.request - WARNING - Not Found: /
2024-01-20 23:11:54,337 - Thread-1 (process_request_thread) - MainProcess - django.server - WARNING - "GET / HTTP/1.1" 404 2275
2024-01-20 23:11:54,693 - Thread-1 (process_request_thread) - MainProcess - django.request - WARNING - Not Found: /favicon.ico
2024-01-20 23:11:54,704 - Thread-1 (process_request_thread) - MainProcess - django.server - WARNING - "GET /favicon.ico HTTP/1.1" 404 2326
2024-01-20 23:12:02,315 - Thread-1 (process_request_thread) - MainProcess - django.server - INFO - "GET /admin/ HTTP/1.1" 302 0
2024-01-20 23:12:02,378 - Thread-1 (process_request_thread) - MainProcess - django.server - INFO - "GET /admin/login/?next=/admin/ HTTP/1.1" 200 4155
2024-01-20 23:12:02,456 - Thread-2 (process_request_thread) - MainProcess - django.server - INFO - "GET /static/admin/css/dark_mode.css HTTP/1.1" 304 0
2024-01-20 23:12:02,459 - Thread-1 (process_request_thread) - MainProcess - django.server - INFO - "GET /static/admin/css/base.css HTTP/1.1" 304 0
2024-01-20 23:12:02,462 - Thread-4 (process_request_thread) - MainProcess - django.server - INFO - "GET /static/admin/css/login.css HTTP/1.1" 304 0
2024-01-20 23:12:02,464 - Thread-5 (process_request_thread) - MainProcess - django.server - INFO - "GET /static/admin/css/responsive.css HTTP/1.1" 304 0
2024-01-20 23:12:02,465 - Thread-3 (process_request_thread) - MainProcess - django.server - INFO - "GET /static/admin/css/nav_sidebar.css HTTP/1.1" 304 0
2024-01-20 23:12:02,470 - Thread-6 (process_request_thread) - MainProcess - django.server - INFO - "GET /static/admin/js/theme.js HTTP/1.1" 304 0
2024-01-20 23:12:02,482 - Thread-6 (process_request_thread) - MainProcess - django.server - INFO - "GET /static/admin/js/nav_sidebar.js HTTP/1.1" 304 0
2024-01-20 23:12:15,494 - Thread-6 (process_request_thread) - MainProcess - django.request - WARNING - Not Found: /api/v1.0/
2024-01-20 23:12:15,495 - Thread-6 (process_request_thread) - MainProcess - django.server - WARNING - "GET /api/v1.0/ HTTP/1.1" 404 2489
2024-01-20 23:12:23,611 - Thread-6 (process_request_thread) - MainProcess - django.request - WARNING - Unauthorized: /api/v1.0/tasks/
2024-01-20 23:12:23,612 - Thread-6 (process_request_thread) - MainProcess - django.server - WARNING - "GET /api/v1.0/tasks/ HTTP/1.1" 401 5086
2024-01-20 23:12:23,633 - Thread-6 (process_request_thread) - MainProcess - django.server - INFO - "GET /static/rest_framework/css/bootstrap-tweaks.css HTTP/1.1" 304 0
2024-01-20 23:12:23,635 - Thread-1 (process_request_thread) - MainProcess - django.server - INFO - "GET /static/rest_framework/css/prettify.css HTTP/1.1" 304 0
2024-01-20 23:12:23,643 - Thread-1 (process_request_thread) - MainProcess - django.server - INFO - "GET /static/rest_framework/css/bootstrap.min.css HTTP/1.1" 304 0
2024-01-20 23:12:23,650 - Thread-2 (process_request_thread) - MainProcess - django.server - INFO - "GET /static/rest_framework/js/csrf.js HTTP/1.1" 304 0
2024-01-20 23:12:23,652 - Thread-3 (process_request_thread) - MainProcess - django.server - INFO - "GET /static/rest_framework/css/default.css HTTP/1.1" 304 0
2024-01-20 23:12:23,653 - Thread-4 (process_request_thread) - MainProcess - django.server - INFO - "GET /static/rest_framework/js/ajax-form.js HTTP/1.1" 304 0
2024-01-20 23:12:23,654 - Thread-5 (process_request_thread) - MainProcess - django.server - INFO - "GET /static/rest_framework/js/jquery-3.5.1.min.js HTTP/1.1" 304 0
2024-01-20 23:12:23,658 - Thread-3 (process_request_thread) - MainProcess - django.server - INFO - "GET /static/rest_framework/js/prettify-min.js HTTP/1.1" 304 0
2024-01-20 23:12:23,661 - Thread-2 (process_request_thread) - MainProcess - django.server - INFO - "GET /static/rest_framework/js/bootstrap.min.js HTTP/1.1" 304 0
2024-01-20 23:12:23,663 - Thread-4 (process_request_thread) - MainProcess - django.server - INFO - "GET /static/rest_framework/js/default.js HTTP/1.1" 304 0
2024-01-20 23:12:23,718 - Thread-4 (process_request_thread) - MainProcess - django.server - INFO - "GET /static/rest_framework/img/grid.png HTTP/1.1" 304 0
2024-01-20 23:13:41,400 - Thread-4 (process_request_thread) - MainProcess - django.request - WARNING - Unauthorized: /api/v1.0/tasks/
2024-01-20 23:13:41,402 - Thread-4 (process_request_thread) - MainProcess - django.server - WARNING - "GET /api/v1.0/tasks/ HTTP/1.1" 401 5086
2024-01-20 23:15:42,424 - MainThread - MainProcess - django.utils.autoreload - INFO - Watching for file changes with StatReloader
2024-01-20 23:15:59,525 - Thread-1 (process_request_thread) - MainProcess - django.server - INFO - "GET /admin/ HTTP/1.1" 302 0
2024-01-20 23:15:59,613 - Thread-1 (process_request_thread) - MainProcess - django.server - INFO - "GET /admin/login/?next=/admin/ HTTP/1.1" 200 4155
2024-01-20 23:16:19,692 - Thread-1 (process_request_thread) - MainProcess - django.server - INFO - "POST /admin/login/?next=/admin/ HTTP/1.1" 302 0
2024-01-20 23:16:19,726 - Thread-1 (process_request_thread) - MainProcess - django.server - INFO - "GET /admin/ HTTP/1.1" 200 5836
2024-01-20 23:16:19,786 - Thread-1 (process_request_thread) - MainProcess - django.server - INFO - "GET /static/admin/css/dashboard.css HTTP/1.1" 304 0
2024-01-20 23:16:19,840 - Thread-1 (process_request_thread) - MainProcess - django.server - INFO - "GET /static/admin/img/icon-addlink.svg HTTP/1.1" 304 0
2024-01-20 23:16:19,842 - Thread-2 (process_request_thread) - MainProcess - django.server - INFO - "GET /static/admin/img/icon-changelink.svg HTTP/1.1" 304 0
2024-01-20 23:16:26,424 - Thread-1 (process_request_thread) - MainProcess - django.server - INFO - "GET /admin/authentication/user/ HTTP/1.1" 200 8501
2024-01-20 23:16:26,472 - Thread-4 (process_request_thread) - MainProcess - django.server - INFO - "GET /static/admin/css/changelists.css HTTP/1.1" 304 0
2024-01-20 23:16:26,491 - Thread-5 (process_request_thread) - MainProcess - django.server - INFO - "GET /static/admin/js/jquery.init.js HTTP/1.1" 304 0
2024-01-20 23:16:26,492 - Thread-4 (process_request_thread) - MainProcess - django.server - INFO - "GET /static/admin/js/admin/RelatedObjectLookups.js HTTP/1.1" 304 0
2024-01-20 23:16:26,499 - Thread-1 (process_request_thread) - MainProcess - django.server - INFO - "GET /admin/jsi18n/ HTTP/1.1" 200 3342
2024-01-20 23:16:26,511 - Thread-6 (process_request_thread) - MainProcess - django.server - INFO - "GET /static/admin/js/core.js HTTP/1.1" 304 0
2024-01-20 23:16:26,515 - Thread-2 (process_request_thread) - MainProcess - django.server - INFO - "GET /static/admin/js/vendor/jquery/jquery.js HTTP/1.1" 200 285314
2024-01-20 23:16:26,516 - Thread-5 (process_request_thread) - MainProcess - django.server - INFO - "GET /static/admin/js/actions.js HTTP/1.1" 304 0
2024-01-20 23:16:26,522 - Thread-3 (process_request_thread) - MainProcess - django.server - INFO - "GET /static/admin/js/vendor/xregexp/xregexp.js HTTP/1.1" 200 325171
2024-01-20 23:16:26,527 - Thread-6 (process_request_thread) - MainProcess - django.server - INFO - "GET /static/admin/js/prepopulate.js HTTP/1.1" 304 0
2024-01-20 23:16:26,533 - Thread-1 (process_request_thread) - MainProcess - django.server - INFO - "GET /static/admin/js/urlify.js HTTP/1.1" 304 0
2024-01-20 23:16:26,607 - Thread-1 (process_request_thread) - MainProcess - django.server - INFO - "GET /static/admin/js/filters.js HTTP/1.1" 304 0
2024-01-20 23:16:26,665 - Thread-1 (process_request_thread) - MainProcess - django.server - INFO - "GET /static/admin/img/tooltag-add.svg HTTP/1.1" 304 0
2024-01-20 23:40:54,739 - MainThread - MainProcess - django.utils.autoreload - INFO - Watching for file changes with StatReloader
2024-01-20 23:41:20,129 - Thread-1 (process_request_thread) - MainProcess - django.request - WARNING - Not Found: /
2024-01-20 23:41:20,131 - Thread-1 (process_request_thread) - MainProcess - django.server - WARNING - "GET / HTTP/1.1" 404 2281
2024-01-20 23:41:34,937 - Thread-1 (process_request_thread) - MainProcess - django.request - WARNING - Not Found: /authentication/
2024-01-20 23:41:34,938 - Thread-1 (process_request_thread) - MainProcess - django.server - WARNING - "GET /authentication/ HTTP/1.1" 404 2229
2024-01-20 23:41:45,011 - Thread-1 (process_request_thread) - MainProcess - django.request - WARNING - Not Found: /authentication/api/v1.0/
2024-01-20 23:41:45,013 - Thread-1 (process_request_thread) - MainProcess - django.server - WARNING - "GET /authentication/api/v1.0/ HTTP/1.1" 404 2256
2024-01-20 23:42:07,543 - Thread-1 (process_request_thread) - MainProcess - django.request - WARNING - Not Found: /authentication/create
2024-01-20 23:42:07,544 - Thread-1 (process_request_thread) - MainProcess - django.server - WARNING - "GET /authentication/create HTTP/1.1" 404 2247
2024-01-20 23:42:22,691 - Thread-1 (process_request_thread) - MainProcess - django.request - WARNING - Not Found: /authentication/api/v1.0/
2024-01-20 23:42:22,692 - Thread-1 (process_request_thread) - MainProcess - django.server - WARNING - "GET /authentication/api/v1.0/ HTTP/1.1" 404 2256
2024-01-20 23:42:57,296 - MainThread - MainProcess - django.utils.autoreload - INFO - /home/dverdun/Documentos/Programacion_python/Prueba_tecnica/ToDo-Challenge-invera/todo-challenge/Core/Core/urls.py changed, reloading.
2024-01-20 23:42:58,128 - MainThread - MainProcess - django.utils.autoreload - INFO - Watching for file changes with StatReloader
2024-01-20 23:43:05,337 - Thread-1 (process_request_thread) - MainProcess - django.request - WARNING - Not Found: /
2024-01-20 23:43:05,339 - Thread-1 (process_request_thread) - MainProcess - django.server - WARNING - "GET / HTTP/1.1" 404 2275
2024-01-20 23:43:19,221 - Thread-1 (process_request_thread) - MainProcess - django.request - WARNING - Not Found: /api/v1.0/
2024-01-20 23:43:19,222 - Thread-1 (process_request_thread) - MainProcess - django.server - WARNING - "GET /api/v1.0/ HTTP/1.1" 404 2489
2024-01-20 23:43:27,788 - Thread-1 (process_request_thread) - MainProcess - django.request - WARNING - Unauthorized: /api/v1.0/tasks/
2024-01-20 23:43:27,789 - Thread-1 (process_request_thread) - MainProcess - django.server - WARNING - "GET /api/v1.0/tasks/ HTTP/1.1" 401 5086
2024-01-20 23:43:28,564 - Thread-1 (process_request_thread) - MainProcess - django.request - WARNING - Unauthorized: /api/v1.0/tasks/
2024-01-20 23:43:28,565 - Thread-1 (process_request_thread) - MainProcess - django.server - WARNING - "GET /api/v1.0/tasks/ HTTP/1.1" 401 5086
2024-01-20 23:46:30,663 - Thread-3 (process_request_thread) - MainProcess - django.request - WARNING - Not Found: /api/v1.0/create/
2024-01-20 23:46:30,664 - Thread-3 (process_request_thread) - MainProcess - django.server - WARNING - "POST /api/v1.0/create/ HTTP/1.1" 404 2511
2024-01-20 23:46:57,053 - Thread-3 (process_request_thread) - MainProcess - django.request - WARNING - Not Found: /api/v1.0/
2024-01-20 23:46:57,054 - Thread-3 (process_request_thread) - MainProcess - django.server - WARNING - "POST /api/v1.0/ HTTP/1.1" 404 2490
2024-01-20 23:47:11,268 - Thread-3 (process_request_thread) - MainProcess - django.request - WARNING - Unauthorized: /api/v1.0/tasks/
2024-01-20 23:47:11,269 - Thread-3 (process_request_thread) - MainProcess - django.server - WARNING - "POST /api/v1.0/tasks/ HTTP/1.1" 401 58
2024-01-20 23:47:43,453 - Thread-3 (process_request_thread) - MainProcess - django.request - WARNING - Unauthorized: /api/v1.0/tasks/
2024-01-20 23:47:43,454 - Thread-3 (process_request_thread) - MainProcess - django.server - WARNING - "GET /api/v1.0/tasks/ HTTP/1.1" 401 58
2024-01-20 23:49:14,286 - Thread-3 (process_request_thread) - MainProcess - django.request - WARNING - Not Found: /api/v1.0/create
2024-01-20 23:49:14,286 - Thread-3 (process_request_thread) - MainProcess - django.server - WARNING - "GET /api/v1.0/create HTTP/1.1" 404 2507
2024-01-20 23:50:53,155 - MainThread - MainProcess - django.utils.autoreload - INFO - /home/dverdun/Documentos/Programacion_python/Prueba_tecnica/ToDo-Challenge-invera/todo-challenge/Core/authentication/urls.py changed, reloading.
2024-01-20 23:50:53,858 - MainThread - MainProcess - django.utils.autoreload - INFO - Watching for file changes with StatReloader
2024-01-20 23:51:41,609 - MainThread - MainProcess - django.utils.autoreload - INFO - Watching for file changes with StatReloader
2024-01-20 23:54:15,171 - MainThread - MainProcess - django.utils.autoreload - INFO - /home/dverdun/Documentos/Programacion_python/Prueba_tecnica/ToDo-Challenge-invera/todo-challenge/Core/authentication/views.py changed, reloading.
2024-01-20 23:54:16,009 - MainThread - MainProcess - django.utils.autoreload - INFO - Watching for file changes with StatReloader
2024-01-20 23:54:56,675 - MainThread - MainProcess - django.utils.autoreload - INFO - Watching for file changes with StatReloader
2024-01-20 23:55:04,471 - Thread-1 (process_request_thread) - MainProcess - django.request - WARNING - Method Not Allowed: /authentication/create/
2024-01-20 23:55:04,472 - Thread-1 (process_request_thread) - MainProcess - django.server - WARNING - "GET /authentication/create/ HTTP/1.1" 405 40
2024-01-20 23:55:11,180 - Thread-1 (process_request_thread) - MainProcess - django.request - ERROR - Internal Server Error: /authentication/create/
Traceback (most recent call last):
  File "/home/dverdun/.local/lib/python3.10/site-packages/django/core/handlers/exception.py", line 55, in inner
    response = get_response(request)
  File "/home/dverdun/.local/lib/python3.10/site-packages/django/core/handlers/base.py", line 197, in _get_response
    response = wrapped_callback(request, *callback_args, **callback_kwargs)
  File "/home/dverdun/.local/lib/python3.10/site-packages/django/views/decorators/csrf.py", line 65, in _view_wrapper
    return view_func(request, *args, **kwargs)
  File "/home/dverdun/.local/lib/python3.10/site-packages/django/views/generic/base.py", line 104, in view
    return self.dispatch(request, *args, **kwargs)
  File "/home/dverdun/.local/lib/python3.10/site-packages/rest_framework/views.py", line 509, in dispatch
    response = self.handle_exception(exc)
  File "/home/dverdun/.local/lib/python3.10/site-packages/rest_framework/views.py", line 469, in handle_exception
    self.raise_uncaught_exception(exc)
  File "/home/dverdun/.local/lib/python3.10/site-packages/rest_framework/views.py", line 480, in raise_uncaught_exception
    raise exc
  File "/home/dverdun/.local/lib/python3.10/site-packages/rest_framework/views.py", line 506, in dispatch
    response = handler(request, *args, **kwargs)
  File "/home/dverdun/.local/lib/python3.10/site-packages/rest_framework/generics.py", line 190, in post
    return self.create(request, *args, **kwargs)
  File "/home/dverdun/.local/lib/python3.10/site-packages/rest_framework/mixins.py", line 18, in create
    serializer.is_valid(raise_exception=True)
  File "/home/dverdun/.local/lib/python3.10/site-packages/rest_framework/serializers.py", line 227, in is_valid
    self._validated_data = self.run_validation(self.initial_data)
  File "/home/dverdun/.local/lib/python3.10/site-packages/rest_framework/serializers.py", line 426, in run_validation
    value = self.to_internal_value(data)
  File "/home/dverdun/.local/lib/python3.10/site-packages/rest_framework/serializers.py", line 479, in to_internal_value
    for field in fields:
  File "/home/dverdun/.local/lib/python3.10/site-packages/rest_framework/serializers.py", line 362, in _writable_fields
    for field in self.fields.values():
  File "/home/dverdun/.local/lib/python3.10/site-packages/django/utils/functional.py", line 47, in __get__
    res = instance.__dict__[self.name] = self.func(instance)
  File "/home/dverdun/.local/lib/python3.10/site-packages/rest_framework/serializers.py", line 356, in fields
    for key, value in self.get_fields().items():
  File "/home/dverdun/.local/lib/python3.10/site-packages/rest_framework/serializers.py", line 1076, in get_fields
    field_class, field_kwargs = self.build_field(
  File "/home/dverdun/.local/lib/python3.10/site-packages/rest_framework/serializers.py", line 1222, in build_field
    return self.build_unknown_field(field_name, model_class)
  File "/home/dverdun/.local/lib/python3.10/site-packages/rest_framework/serializers.py", line 1340, in build_unknown_field
    raise ImproperlyConfigured(
django.core.exceptions.ImproperlyConfigured: Field name `email,` is not valid for model `User`.
2024-01-20 23:55:11,192 - Thread-1 (process_request_thread) - MainProcess - django.server - ERROR - "POST /authentication/create/ HTTP/1.1" 500 139275
2024-01-20 23:56:45,622 - Thread-1 (process_request_thread) - MainProcess - django.request - WARNING - Bad Request: /authentication/create/
2024-01-20 23:56:45,623 - Thread-1 (process_request_thread) - MainProcess - django.server - WARNING - "POST /authentication/create/ HTTP/1.1" 400 73
2024-01-20 23:56:56,634 - Thread-1 (process_request_thread) - MainProcess - django.request - ERROR - Internal Server Error: /authentication/create/
Traceback (most recent call last):
  File "/home/dverdun/.local/lib/python3.10/site-packages/django/core/handlers/exception.py", line 55, in inner
    response = get_response(request)
  File "/home/dverdun/.local/lib/python3.10/site-packages/django/core/handlers/base.py", line 197, in _get_response
    response = wrapped_callback(request, *callback_args, **callback_kwargs)
  File "/home/dverdun/.local/lib/python3.10/site-packages/django/views/decorators/csrf.py", line 65, in _view_wrapper
    return view_func(request, *args, **kwargs)
  File "/home/dverdun/.local/lib/python3.10/site-packages/django/views/generic/base.py", line 104, in view
    return self.dispatch(request, *args, **kwargs)
  File "/home/dverdun/.local/lib/python3.10/site-packages/rest_framework/views.py", line 509, in dispatch
    response = self.handle_exception(exc)
  File "/home/dverdun/.local/lib/python3.10/site-packages/rest_framework/views.py", line 469, in handle_exception
    self.raise_uncaught_exception(exc)
  File "/home/dverdun/.local/lib/python3.10/site-packages/rest_framework/views.py", line 480, in raise_uncaught_exception
    raise exc
  File "/home/dverdun/.local/lib/python3.10/site-packages/rest_framework/views.py", line 506, in dispatch
    response = handler(request, *args, **kwargs)
  File "/home/dverdun/.local/lib/python3.10/site-packages/rest_framework/generics.py", line 190, in post
    return self.create(request, *args, **kwargs)
  File "/home/dverdun/.local/lib/python3.10/site-packages/rest_framework/mixins.py", line 18, in create
    serializer.is_valid(raise_exception=True)
  File "/home/dverdun/.local/lib/python3.10/site-packages/rest_framework/serializers.py", line 227, in is_valid
    self._validated_data = self.run_validation(self.initial_data)
  File "/home/dverdun/.local/lib/python3.10/site-packages/rest_framework/serializers.py", line 426, in run_validation
    value = self.to_internal_value(data)
  File "/home/dverdun/.local/lib/python3.10/site-packages/rest_framework/serializers.py", line 479, in to_internal_value
    for field in fields:
  File "/home/dverdun/.local/lib/python3.10/site-packages/rest_framework/serializers.py", line 362, in _writable_fields
    for field in self.fields.values():
  File "/home/dverdun/.local/lib/python3.10/site-packages/django/utils/functional.py", line 47, in __get__
    res = instance.__dict__[self.name] = self.func(instance)
  File "/home/dverdun/.local/lib/python3.10/site-packages/rest_framework/serializers.py", line 356, in fields
    for key, value in self.get_fields().items():
  File "/home/dverdun/.local/lib/python3.10/site-packages/rest_framework/serializers.py", line 1076, in get_fields
    field_class, field_kwargs = self.build_field(
  File "/home/dverdun/.local/lib/python3.10/site-packages/rest_framework/serializers.py", line 1222, in build_field
    return self.build_unknown_field(field_name, model_class)
  File "/home/dverdun/.local/lib/python3.10/site-packages/rest_framework/serializers.py", line 1340, in build_unknown_field
    raise ImproperlyConfigured(
django.core.exceptions.ImproperlyConfigured: Field name `email,` is not valid for model `User`.
2024-01-20 23:56:56,636 - Thread-1 (process_request_thread) - MainProcess - django.server - ERROR - "POST /authentication/create/ HTTP/1.1" 500 139269
2024-01-20 23:57:52,149 - MainThread - MainProcess - django.utils.autoreload - INFO - /home/dverdun/Documentos/Programacion_python/Prueba_tecnica/ToDo-Challenge-invera/todo-challenge/Core/authentication/views.py changed, reloading.
2024-01-20 23:57:52,948 - MainThread - MainProcess - django.utils.autoreload - INFO - Watching for file changes with StatReloader
2024-01-20 23:57:58,719 - Thread-1 (process_request_thread) - MainProcess - django.request - ERROR - Internal Server Error: /authentication/create/
Traceback (most recent call last):
  File "/home/dverdun/.local/lib/python3.10/site-packages/django/core/handlers/exception.py", line 55, in inner
    response = get_response(request)
  File "/home/dverdun/.local/lib/python3.10/site-packages/django/core/handlers/base.py", line 197, in _get_response
    response = wrapped_callback(request, *callback_args, **callback_kwargs)
  File "/home/dverdun/.local/lib/python3.10/site-packages/django/views/decorators/csrf.py", line 65, in _view_wrapper
    return view_func(request, *args, **kwargs)
  File "/home/dverdun/.local/lib/python3.10/site-packages/django/views/generic/base.py", line 104, in view
    return self.dispatch(request, *args, **kwargs)
  File "/home/dverdun/.local/lib/python3.10/site-packages/rest_framework/views.py", line 509, in dispatch
    response = self.handle_exception(exc)
  File "/home/dverdun/.local/lib/python3.10/site-packages/rest_framework/views.py", line 469, in handle_exception
    self.raise_uncaught_exception(exc)
  File "/home/dverdun/.local/lib/python3.10/site-packages/rest_framework/views.py", line 480, in raise_uncaught_exception
    raise exc
  File "/home/dverdun/.local/lib/python3.10/site-packages/rest_framework/views.py", line 506, in dispatch
    response = handler(request, *args, **kwargs)
  File "/home/dverdun/.local/lib/python3.10/site-packages/rest_framework/generics.py", line 190, in post
    return self.create(request, *args, **kwargs)
  File "/home/dverdun/.local/lib/python3.10/site-packages/rest_framework/mixins.py", line 18, in create
    serializer.is_valid(raise_exception=True)
  File "/home/dverdun/.local/lib/python3.10/site-packages/rest_framework/serializers.py", line 227, in is_valid
    self._validated_data = self.run_validation(self.initial_data)
  File "/home/dverdun/.local/lib/python3.10/site-packages/rest_framework/serializers.py", line 426, in run_validation
    value = self.to_internal_value(data)
  File "/home/dverdun/.local/lib/python3.10/site-packages/rest_framework/serializers.py", line 479, in to_internal_value
    for field in fields:
  File "/home/dverdun/.local/lib/python3.10/site-packages/rest_framework/serializers.py", line 362, in _writable_fields
    for field in self.fields.values():
  File "/home/dverdun/.local/lib/python3.10/site-packages/django/utils/functional.py", line 47, in __get__
    res = instance.__dict__[self.name] = self.func(instance)
  File "/home/dverdun/.local/lib/python3.10/site-packages/rest_framework/serializers.py", line 356, in fields
    for key, value in self.get_fields().items():
  File "/home/dverdun/.local/lib/python3.10/site-packages/rest_framework/serializers.py", line 1076, in get_fields
    field_class, field_kwargs = self.build_field(
  File "/home/dverdun/.local/lib/python3.10/site-packages/rest_framework/serializers.py", line 1222, in build_field
    return self.build_unknown_field(field_name, model_class)
  File "/home/dverdun/.local/lib/python3.10/site-packages/rest_framework/serializers.py", line 1340, in build_unknown_field
    raise ImproperlyConfigured(
django.core.exceptions.ImproperlyConfigured: Field name `email,` is not valid for model `User`.
2024-01-20 23:57:58,723 - Thread-1 (process_request_thread) - MainProcess - django.server - ERROR - "POST /authentication/create/ HTTP/1.1" 500 139269
2024-01-20 23:58:07,659 - Thread-1 (process_request_thread) - MainProcess - django.request - ERROR - Internal Server Error: /authentication/create/
Traceback (most recent call last):
  File "/home/dverdun/.local/lib/python3.10/site-packages/django/core/handlers/exception.py", line 55, in inner
    response = get_response(request)
  File "/home/dverdun/.local/lib/python3.10/site-packages/django/core/handlers/base.py", line 197, in _get_response
    response = wrapped_callback(request, *callback_args, **callback_kwargs)
  File "/home/dverdun/.local/lib/python3.10/site-packages/django/views/decorators/csrf.py", line 65, in _view_wrapper
    return view_func(request, *args, **kwargs)
  File "/home/dverdun/.local/lib/python3.10/site-packages/django/views/generic/base.py", line 104, in view
    return self.dispatch(request, *args, **kwargs)
  File "/home/dverdun/.local/lib/python3.10/site-packages/rest_framework/views.py", line 509, in dispatch
    response = self.handle_exception(exc)
  File "/home/dverdun/.local/lib/python3.10/site-packages/rest_framework/views.py", line 469, in handle_exception
    self.raise_uncaught_exception(exc)
  File "/home/dverdun/.local/lib/python3.10/site-packages/rest_framework/views.py", line 480, in raise_uncaught_exception
    raise exc
  File "/home/dverdun/.local/lib/python3.10/site-packages/rest_framework/views.py", line 506, in dispatch
    response = handler(request, *args, **kwargs)
  File "/home/dverdun/.local/lib/python3.10/site-packages/rest_framework/generics.py", line 190, in post
    return self.create(request, *args, **kwargs)
  File "/home/dverdun/.local/lib/python3.10/site-packages/rest_framework/mixins.py", line 18, in create
    serializer.is_valid(raise_exception=True)
  File "/home/dverdun/.local/lib/python3.10/site-packages/rest_framework/serializers.py", line 227, in is_valid
    self._validated_data = self.run_validation(self.initial_data)
  File "/home/dverdun/.local/lib/python3.10/site-packages/rest_framework/serializers.py", line 426, in run_validation
    value = self.to_internal_value(data)
  File "/home/dverdun/.local/lib/python3.10/site-packages/rest_framework/serializers.py", line 479, in to_internal_value
    for field in fields:
  File "/home/dverdun/.local/lib/python3.10/site-packages/rest_framework/serializers.py", line 362, in _writable_fields
    for field in self.fields.values():
  File "/home/dverdun/.local/lib/python3.10/site-packages/django/utils/functional.py", line 47, in __get__
    res = instance.__dict__[self.name] = self.func(instance)
  File "/home/dverdun/.local/lib/python3.10/site-packages/rest_framework/serializers.py", line 356, in fields
    for key, value in self.get_fields().items():
  File "/home/dverdun/.local/lib/python3.10/site-packages/rest_framework/serializers.py", line 1076, in get_fields
    field_class, field_kwargs = self.build_field(
  File "/home/dverdun/.local/lib/python3.10/site-packages/rest_framework/serializers.py", line 1222, in build_field
    return self.build_unknown_field(field_name, model_class)
  File "/home/dverdun/.local/lib/python3.10/site-packages/rest_framework/serializers.py", line 1340, in build_unknown_field
    raise ImproperlyConfigured(
django.core.exceptions.ImproperlyConfigured: Field name `email,` is not valid for model `User`.
2024-01-20 23:58:07,660 - Thread-1 (process_request_thread) - MainProcess - django.server - ERROR - "POST /authentication/create/ HTTP/1.1" 500 139269
2024-01-20 23:58:50,875 - Thread-1 (process_request_thread) - MainProcess - django.request - WARNING - Unauthorized: /authentication/user/
2024-01-20 23:58:50,876 - Thread-1 (process_request_thread) - MainProcess - django.server - WARNING - "POST /authentication/user/ HTTP/1.1" 401 58
2024-01-20 23:59:50,428 - Thread-1 (process_request_thread) - MainProcess - django.request - WARNING - Unauthorized: /api/v1.0/tasks/
2024-01-20 23:59:50,429 - Thread-1 (process_request_thread) - MainProcess - django.server - WARNING - "GET /api/v1.0/tasks/ HTTP/1.1" 401 58
2024-01-21 00:02:57,288 - Thread-1 (process_request_thread) - MainProcess - django.request - ERROR - Internal Server Error: /authentication/create/
Traceback (most recent call last):
  File "/home/dverdun/.local/lib/python3.10/site-packages/django/core/handlers/exception.py", line 55, in inner
    response = get_response(request)
  File "/home/dverdun/.local/lib/python3.10/site-packages/django/core/handlers/base.py", line 197, in _get_response
    response = wrapped_callback(request, *callback_args, **callback_kwargs)
  File "/home/dverdun/.local/lib/python3.10/site-packages/django/views/decorators/csrf.py", line 65, in _view_wrapper
    return view_func(request, *args, **kwargs)
  File "/home/dverdun/.local/lib/python3.10/site-packages/django/views/generic/base.py", line 104, in view
    return self.dispatch(request, *args, **kwargs)
  File "/home/dverdun/.local/lib/python3.10/site-packages/rest_framework/views.py", line 509, in dispatch
    response = self.handle_exception(exc)
  File "/home/dverdun/.local/lib/python3.10/site-packages/rest_framework/views.py", line 469, in handle_exception
    self.raise_uncaught_exception(exc)
  File "/home/dverdun/.local/lib/python3.10/site-packages/rest_framework/views.py", line 480, in raise_uncaught_exception
    raise exc
  File "/home/dverdun/.local/lib/python3.10/site-packages/rest_framework/views.py", line 506, in dispatch
    response = handler(request, *args, **kwargs)
  File "/home/dverdun/.local/lib/python3.10/site-packages/rest_framework/generics.py", line 190, in post
    return self.create(request, *args, **kwargs)
  File "/home/dverdun/.local/lib/python3.10/site-packages/rest_framework/mixins.py", line 18, in create
    serializer.is_valid(raise_exception=True)
  File "/home/dverdun/.local/lib/python3.10/site-packages/rest_framework/serializers.py", line 227, in is_valid
    self._validated_data = self.run_validation(self.initial_data)
  File "/home/dverdun/.local/lib/python3.10/site-packages/rest_framework/serializers.py", line 426, in run_validation
    value = self.to_internal_value(data)
  File "/home/dverdun/.local/lib/python3.10/site-packages/rest_framework/serializers.py", line 479, in to_internal_value
    for field in fields:
  File "/home/dverdun/.local/lib/python3.10/site-packages/rest_framework/serializers.py", line 362, in _writable_fields
    for field in self.fields.values():
  File "/home/dverdun/.local/lib/python3.10/site-packages/django/utils/functional.py", line 47, in __get__
    res = instance.__dict__[self.name] = self.func(instance)
  File "/home/dverdun/.local/lib/python3.10/site-packages/rest_framework/serializers.py", line 356, in fields
    for key, value in self.get_fields().items():
  File "/home/dverdun/.local/lib/python3.10/site-packages/rest_framework/serializers.py", line 1076, in get_fields
    field_class, field_kwargs = self.build_field(
  File "/home/dverdun/.local/lib/python3.10/site-packages/rest_framework/serializers.py", line 1222, in build_field
    return self.build_unknown_field(field_name, model_class)
  File "/home/dverdun/.local/lib/python3.10/site-packages/rest_framework/serializers.py", line 1340, in build_unknown_field
    raise ImproperlyConfigured(
django.core.exceptions.ImproperlyConfigured: Field name `email,` is not valid for model `User`.
2024-01-21 00:02:57,289 - Thread-1 (process_request_thread) - MainProcess - django.server - ERROR - "POST /authentication/create/ HTTP/1.1" 500 139536
2024-01-21 00:04:24,708 - MainThread - MainProcess - django.utils.autoreload - INFO - /home/dverdun/Documentos/Programacion_python/Prueba_tecnica/ToDo-Challenge-invera/todo-challenge/Core/Core/settings.py changed, reloading.
2024-01-21 00:04:25,554 - MainThread - MainProcess - django.utils.autoreload - INFO - Watching for file changes with StatReloader
2024-01-21 00:05:24,845 - MainThread - MainProcess - django.utils.autoreload - INFO - Watching for file changes with StatReloader
2024-01-21 00:25:26,002 - MainThread - MainProcess - django.utils.autoreload - INFO - Watching for file changes with StatReloader
2024-01-21 00:26:19,201 - Thread-1 (process_request_thread) - MainProcess - django.request - ERROR - Internal Server Error: /api/v1.0/create/
Traceback (most recent call last):
  File "/home/dverdun/.local/lib/python3.10/site-packages/django/core/handlers/exception.py", line 55, in inner
    response = get_response(request)
  File "/home/dverdun/.local/lib/python3.10/site-packages/django/core/handlers/base.py", line 197, in _get_response
    response = wrapped_callback(request, *callback_args, **callback_kwargs)
  File "/home/dverdun/.local/lib/python3.10/site-packages/django/views/decorators/csrf.py", line 65, in _view_wrapper
    return view_func(request, *args, **kwargs)
  File "/home/dverdun/.local/lib/python3.10/site-packages/django/views/generic/base.py", line 104, in view
    return self.dispatch(request, *args, **kwargs)
  File "/home/dverdun/.local/lib/python3.10/site-packages/rest_framework/views.py", line 509, in dispatch
    response = self.handle_exception(exc)
  File "/home/dverdun/.local/lib/python3.10/site-packages/rest_framework/views.py", line 469, in handle_exception
    self.raise_uncaught_exception(exc)
  File "/home/dverdun/.local/lib/python3.10/site-packages/rest_framework/views.py", line 480, in raise_uncaught_exception
    raise exc
  File "/home/dverdun/.local/lib/python3.10/site-packages/rest_framework/views.py", line 506, in dispatch
    response = handler(request, *args, **kwargs)
  File "/home/dverdun/.local/lib/python3.10/site-packages/rest_framework/generics.py", line 190, in post
    return self.create(request, *args, **kwargs)
  File "/home/dverdun/.local/lib/python3.10/site-packages/rest_framework/mixins.py", line 18, in create
    serializer.is_valid(raise_exception=True)
  File "/home/dverdun/.local/lib/python3.10/site-packages/rest_framework/serializers.py", line 227, in is_valid
    self._validated_data = self.run_validation(self.initial_data)
  File "/home/dverdun/.local/lib/python3.10/site-packages/rest_framework/serializers.py", line 426, in run_validation
    value = self.to_internal_value(data)
  File "/home/dverdun/.local/lib/python3.10/site-packages/rest_framework/serializers.py", line 479, in to_internal_value
    for field in fields:
  File "/home/dverdun/.local/lib/python3.10/site-packages/rest_framework/serializers.py", line 362, in _writable_fields
    for field in self.fields.values():
  File "/home/dverdun/.local/lib/python3.10/site-packages/django/utils/functional.py", line 47, in __get__
    res = instance.__dict__[self.name] = self.func(instance)
  File "/home/dverdun/.local/lib/python3.10/site-packages/rest_framework/serializers.py", line 356, in fields
    for key, value in self.get_fields().items():
  File "/home/dverdun/.local/lib/python3.10/site-packages/rest_framework/serializers.py", line 1076, in get_fields
    field_class, field_kwargs = self.build_field(
  File "/home/dverdun/.local/lib/python3.10/site-packages/rest_framework/serializers.py", line 1222, in build_field
    return self.build_unknown_field(field_name, model_class)
  File "/home/dverdun/.local/lib/python3.10/site-packages/rest_framework/serializers.py", line 1340, in build_unknown_field
    raise ImproperlyConfigured(
django.core.exceptions.ImproperlyConfigured: Field name `email,` is not valid for model `User`.
2024-01-21 00:26:19,205 - Thread-1 (process_request_thread) - MainProcess - django.server - ERROR - "POST /api/v1.0/create/ HTTP/1.1" 500 139263
2024-01-21 00:26:31,479 - Thread-2 (process_request_thread) - MainProcess - django.request - WARNING - Not Found: /api/v1.0/
2024-01-21 00:26:31,480 - Thread-2 (process_request_thread) - MainProcess - django.server - WARNING - "GET /api/v1.0/ HTTP/1.1" 404 2975
2024-01-21 00:26:59,593 - Thread-2 (process_request_thread) - MainProcess - django.request - WARNING - Not Found: /api/v1.0/ create/
2024-01-21 00:26:59,594 - Thread-2 (process_request_thread) - MainProcess - django.server - WARNING - "GET /api/v1.0/%20create/ HTTP/1.1" 404 3001
2024-01-21 00:27:13,349 - Thread-2 (process_request_thread) - MainProcess - django.request - ERROR - Internal Server Error: /api/v1.0/create/
Traceback (most recent call last):
  File "/home/dverdun/.local/lib/python3.10/site-packages/django/core/handlers/exception.py", line 55, in inner
    response = get_response(request)
  File "/home/dverdun/.local/lib/python3.10/site-packages/django/core/handlers/base.py", line 220, in _get_response
    response = response.render()
  File "/home/dverdun/.local/lib/python3.10/site-packages/django/template/response.py", line 114, in render
    self.content = self.rendered_content
  File "/home/dverdun/.local/lib/python3.10/site-packages/rest_framework/response.py", line 70, in rendered_content
    ret = renderer.render(self.data, accepted_media_type, context)
  File "/home/dverdun/.local/lib/python3.10/site-packages/rest_framework/renderers.py", line 723, in render
    context = self.get_context(data, accepted_media_type, renderer_context)
  File "/home/dverdun/.local/lib/python3.10/site-packages/rest_framework/renderers.py", line 654, in get_context
    raw_data_post_form = self.get_raw_data_form(data, view, 'POST', request)
  File "/home/dverdun/.local/lib/python3.10/site-packages/rest_framework/renderers.py", line 562, in get_raw_data_form
    data = serializer.data.copy()
  File "/home/dverdun/.local/lib/python3.10/site-packages/rest_framework/serializers.py", line 555, in data
    ret = super().data
  File "/home/dverdun/.local/lib/python3.10/site-packages/rest_framework/serializers.py", line 257, in data
    self._data = self.get_initial()
  File "/home/dverdun/.local/lib/python3.10/site-packages/rest_framework/serializers.py", line 405, in get_initial
    for field in self.fields.values()
  File "/home/dverdun/.local/lib/python3.10/site-packages/django/utils/functional.py", line 47, in __get__
    res = instance.__dict__[self.name] = self.func(instance)
  File "/home/dverdun/.local/lib/python3.10/site-packages/rest_framework/serializers.py", line 356, in fields
    for key, value in self.get_fields().items():
  File "/home/dverdun/.local/lib/python3.10/site-packages/rest_framework/serializers.py", line 1076, in get_fields
    field_class, field_kwargs = self.build_field(
  File "/home/dverdun/.local/lib/python3.10/site-packages/rest_framework/serializers.py", line 1222, in build_field
    return self.build_unknown_field(field_name, model_class)
  File "/home/dverdun/.local/lib/python3.10/site-packages/rest_framework/serializers.py", line 1340, in build_unknown_field
    raise ImproperlyConfigured(
django.core.exceptions.ImproperlyConfigured: Field name `email,` is not valid for model `User`.
2024-01-21 00:27:13,351 - Thread-2 (process_request_thread) - MainProcess - django.server - ERROR - "GET /api/v1.0/create/ HTTP/1.1" 500 127510
2024-01-21 00:29:18,040 - Thread-1 (process_request_thread) - MainProcess - django.request - WARNING - Not Found: /users/create/
2024-01-21 00:29:18,041 - Thread-1 (process_request_thread) - MainProcess - django.server - WARNING - "POST /users/create/ HTTP/1.1" 404 2333
2024-01-21 00:30:07,301 - Thread-2 (process_request_thread) - MainProcess - django.request - WARNING - Not Found: /users/create/
2024-01-21 00:30:07,302 - Thread-2 (process_request_thread) - MainProcess - django.server - WARNING - "GET /users/create/ HTTP/1.1" 404 2332
2024-01-21 00:30:38,755 - MainThread - MainProcess - django.utils.autoreload - INFO - /home/dverdun/Documentos/Programacion_python/Prueba_tecnica/ToDo-Challenge-invera/todo-challenge/Core/Core/urls.py changed, reloading.
2024-01-21 00:30:39,631 - MainThread - MainProcess - django.utils.autoreload - INFO - Watching for file changes with StatReloader
2024-01-21 00:30:40,783 - Thread-1 (process_request_thread) - MainProcess - django.request - ERROR - Internal Server Error: /users/create/
Traceback (most recent call last):
  File "/home/dverdun/.local/lib/python3.10/site-packages/django/core/handlers/exception.py", line 55, in inner
    response = get_response(request)
  File "/home/dverdun/.local/lib/python3.10/site-packages/django/core/handlers/base.py", line 220, in _get_response
    response = response.render()
  File "/home/dverdun/.local/lib/python3.10/site-packages/django/template/response.py", line 114, in render
    self.content = self.rendered_content
  File "/home/dverdun/.local/lib/python3.10/site-packages/rest_framework/response.py", line 70, in rendered_content
    ret = renderer.render(self.data, accepted_media_type, context)
  File "/home/dverdun/.local/lib/python3.10/site-packages/rest_framework/renderers.py", line 723, in render
    context = self.get_context(data, accepted_media_type, renderer_context)
  File "/home/dverdun/.local/lib/python3.10/site-packages/rest_framework/renderers.py", line 654, in get_context
    raw_data_post_form = self.get_raw_data_form(data, view, 'POST', request)
  File "/home/dverdun/.local/lib/python3.10/site-packages/rest_framework/renderers.py", line 562, in get_raw_data_form
    data = serializer.data.copy()
  File "/home/dverdun/.local/lib/python3.10/site-packages/rest_framework/serializers.py", line 555, in data
    ret = super().data
  File "/home/dverdun/.local/lib/python3.10/site-packages/rest_framework/serializers.py", line 257, in data
    self._data = self.get_initial()
  File "/home/dverdun/.local/lib/python3.10/site-packages/rest_framework/serializers.py", line 405, in get_initial
    for field in self.fields.values()
  File "/home/dverdun/.local/lib/python3.10/site-packages/django/utils/functional.py", line 47, in __get__
    res = instance.__dict__[self.name] = self.func(instance)
  File "/home/dverdun/.local/lib/python3.10/site-packages/rest_framework/serializers.py", line 356, in fields
    for key, value in self.get_fields().items():
  File "/home/dverdun/.local/lib/python3.10/site-packages/rest_framework/serializers.py", line 1076, in get_fields
    field_class, field_kwargs = self.build_field(
  File "/home/dverdun/.local/lib/python3.10/site-packages/rest_framework/serializers.py", line 1222, in build_field
    return self.build_unknown_field(field_name, model_class)
  File "/home/dverdun/.local/lib/python3.10/site-packages/rest_framework/serializers.py", line 1340, in build_unknown_field
    raise ImproperlyConfigured(
django.core.exceptions.ImproperlyConfigured: Field name `email,` is not valid for model `User`.
2024-01-21 00:30:40,787 - Thread-1 (process_request_thread) - MainProcess - django.server - ERROR - "GET /users/create/ HTTP/1.1" 500 127453
2024-01-21 00:32:21,892 - Thread-3 (process_request_thread) - MainProcess - django.request - ERROR - Internal Server Error: /users/create/
Traceback (most recent call last):
  File "/home/dverdun/.local/lib/python3.10/site-packages/django/core/handlers/exception.py", line 55, in inner
    response = get_response(request)
  File "/home/dverdun/.local/lib/python3.10/site-packages/django/core/handlers/base.py", line 197, in _get_response
    response = wrapped_callback(request, *callback_args, **callback_kwargs)
  File "/home/dverdun/.local/lib/python3.10/site-packages/django/views/decorators/csrf.py", line 65, in _view_wrapper
    return view_func(request, *args, **kwargs)
  File "/home/dverdun/.local/lib/python3.10/site-packages/django/views/generic/base.py", line 104, in view
    return self.dispatch(request, *args, **kwargs)
  File "/home/dverdun/.local/lib/python3.10/site-packages/rest_framework/views.py", line 509, in dispatch
    response = self.handle_exception(exc)
  File "/home/dverdun/.local/lib/python3.10/site-packages/rest_framework/views.py", line 469, in handle_exception
    self.raise_uncaught_exception(exc)
  File "/home/dverdun/.local/lib/python3.10/site-packages/rest_framework/views.py", line 480, in raise_uncaught_exception
    raise exc
  File "/home/dverdun/.local/lib/python3.10/site-packages/rest_framework/views.py", line 506, in dispatch
    response = handler(request, *args, **kwargs)
  File "/home/dverdun/.local/lib/python3.10/site-packages/rest_framework/generics.py", line 190, in post
    return self.create(request, *args, **kwargs)
  File "/home/dverdun/.local/lib/python3.10/site-packages/rest_framework/mixins.py", line 18, in create
    serializer.is_valid(raise_exception=True)
  File "/home/dverdun/.local/lib/python3.10/site-packages/rest_framework/serializers.py", line 227, in is_valid
    self._validated_data = self.run_validation(self.initial_data)
  File "/home/dverdun/.local/lib/python3.10/site-packages/rest_framework/serializers.py", line 426, in run_validation
    value = self.to_internal_value(data)
  File "/home/dverdun/.local/lib/python3.10/site-packages/rest_framework/serializers.py", line 479, in to_internal_value
    for field in fields:
  File "/home/dverdun/.local/lib/python3.10/site-packages/rest_framework/serializers.py", line 362, in _writable_fields
    for field in self.fields.values():
  File "/home/dverdun/.local/lib/python3.10/site-packages/django/utils/functional.py", line 47, in __get__
    res = instance.__dict__[self.name] = self.func(instance)
  File "/home/dverdun/.local/lib/python3.10/site-packages/rest_framework/serializers.py", line 356, in fields
    for key, value in self.get_fields().items():
  File "/home/dverdun/.local/lib/python3.10/site-packages/rest_framework/serializers.py", line 1076, in get_fields
    field_class, field_kwargs = self.build_field(
  File "/home/dverdun/.local/lib/python3.10/site-packages/rest_framework/serializers.py", line 1222, in build_field
    return self.build_unknown_field(field_name, model_class)
  File "/home/dverdun/.local/lib/python3.10/site-packages/rest_framework/serializers.py", line 1340, in build_unknown_field
    raise ImproperlyConfigured(
django.core.exceptions.ImproperlyConfigured: Field name `email,` is not valid for model `User`.
2024-01-21 00:32:21,894 - Thread-3 (process_request_thread) - MainProcess - django.server - ERROR - "POST /users/create/ HTTP/1.1" 500 139212
2024-01-21 00:32:37,519 - Thread-1 (process_request_thread) - MainProcess - django.request - WARNING - Not Found: /
2024-01-21 00:32:37,519 - Thread-1 (process_request_thread) - MainProcess - django.server - WARNING - "GET / HTTP/1.1" 404 2272
2024-01-21 00:32:50,003 - Thread-1 (process_request_thread) - MainProcess - django.request - WARNING - Not Found: /users
2024-01-21 00:32:50,004 - Thread-1 (process_request_thread) - MainProcess - django.server - WARNING - "GET /users HTTP/1.1" 404 2305
2024-01-21 00:33:02,739 - Thread-1 (process_request_thread) - MainProcess - django.request - WARNING - Not Found: /users/
2024-01-21 00:33:02,740 - Thread-1 (process_request_thread) - MainProcess - django.server - WARNING - "GET /users/ HTTP/1.1" 404 2679
2024-01-21 00:33:34,105 - Thread-3 (process_request_thread) - MainProcess - django.request - ERROR - Internal Server Error: /users/create/
Traceback (most recent call last):
  File "/home/dverdun/.local/lib/python3.10/site-packages/django/core/handlers/exception.py", line 55, in inner
    response = get_response(request)
  File "/home/dverdun/.local/lib/python3.10/site-packages/django/core/handlers/base.py", line 197, in _get_response
    response = wrapped_callback(request, *callback_args, **callback_kwargs)
  File "/home/dverdun/.local/lib/python3.10/site-packages/django/views/decorators/csrf.py", line 65, in _view_wrapper
    return view_func(request, *args, **kwargs)
  File "/home/dverdun/.local/lib/python3.10/site-packages/django/views/generic/base.py", line 104, in view
    return self.dispatch(request, *args, **kwargs)
  File "/home/dverdun/.local/lib/python3.10/site-packages/rest_framework/views.py", line 509, in dispatch
    response = self.handle_exception(exc)
  File "/home/dverdun/.local/lib/python3.10/site-packages/rest_framework/views.py", line 469, in handle_exception
    self.raise_uncaught_exception(exc)
  File "/home/dverdun/.local/lib/python3.10/site-packages/rest_framework/views.py", line 480, in raise_uncaught_exception
    raise exc
  File "/home/dverdun/.local/lib/python3.10/site-packages/rest_framework/views.py", line 506, in dispatch
    response = handler(request, *args, **kwargs)
  File "/home/dverdun/.local/lib/python3.10/site-packages/rest_framework/generics.py", line 190, in post
    return self.create(request, *args, **kwargs)
  File "/home/dverdun/.local/lib/python3.10/site-packages/rest_framework/mixins.py", line 18, in create
    serializer.is_valid(raise_exception=True)
  File "/home/dverdun/.local/lib/python3.10/site-packages/rest_framework/serializers.py", line 227, in is_valid
    self._validated_data = self.run_validation(self.initial_data)
  File "/home/dverdun/.local/lib/python3.10/site-packages/rest_framework/serializers.py", line 426, in run_validation
    value = self.to_internal_value(data)
  File "/home/dverdun/.local/lib/python3.10/site-packages/rest_framework/serializers.py", line 479, in to_internal_value
    for field in fields:
  File "/home/dverdun/.local/lib/python3.10/site-packages/rest_framework/serializers.py", line 362, in _writable_fields
    for field in self.fields.values():
  File "/home/dverdun/.local/lib/python3.10/site-packages/django/utils/functional.py", line 47, in __get__
    res = instance.__dict__[self.name] = self.func(instance)
  File "/home/dverdun/.local/lib/python3.10/site-packages/rest_framework/serializers.py", line 356, in fields
    for key, value in self.get_fields().items():
  File "/home/dverdun/.local/lib/python3.10/site-packages/rest_framework/serializers.py", line 1076, in get_fields
    field_class, field_kwargs = self.build_field(
  File "/home/dverdun/.local/lib/python3.10/site-packages/rest_framework/serializers.py", line 1222, in build_field
    return self.build_unknown_field(field_name, model_class)
  File "/home/dverdun/.local/lib/python3.10/site-packages/rest_framework/serializers.py", line 1340, in build_unknown_field
    raise ImproperlyConfigured(
django.core.exceptions.ImproperlyConfigured: Field name `email,` is not valid for model `User`.
2024-01-21 00:33:34,107 - Thread-3 (process_request_thread) - MainProcess - django.server - ERROR - "POST /users/create/ HTTP/1.1" 500 139212
2024-01-21 00:34:32,004 - Thread-1 (process_request_thread) - MainProcess - django.server - INFO - "GET /users/user HTTP/1.1" 301 0
2024-01-21 00:34:32,034 - Thread-5 (process_request_thread) - MainProcess - django.request - WARNING - Unauthorized: /users/user/
2024-01-21 00:34:32,035 - Thread-5 (process_request_thread) - MainProcess - django.server - WARNING - "GET /users/user/ HTTP/1.1" 401 5138
2024-01-21 00:34:41,424 - Thread-5 (process_request_thread) - MainProcess - django.request - WARNING - Not Found: /users/
2024-01-21 00:34:41,425 - Thread-5 (process_request_thread) - MainProcess - django.server - WARNING - "GET /users/ HTTP/1.1" 404 2679
2024-01-21 00:34:49,800 - Thread-5 (process_request_thread) - MainProcess - django.server - INFO - "GET /users/create HTTP/1.1" 301 0
2024-01-21 00:34:49,870 - Thread-6 (process_request_thread) - MainProcess - django.request - ERROR - Internal Server Error: /users/create/
Traceback (most recent call last):
  File "/home/dverdun/.local/lib/python3.10/site-packages/django/core/handlers/exception.py", line 55, in inner
    response = get_response(request)
  File "/home/dverdun/.local/lib/python3.10/site-packages/django/core/handlers/base.py", line 220, in _get_response
    response = response.render()
  File "/home/dverdun/.local/lib/python3.10/site-packages/django/template/response.py", line 114, in render
    self.content = self.rendered_content
  File "/home/dverdun/.local/lib/python3.10/site-packages/rest_framework/response.py", line 70, in rendered_content
    ret = renderer.render(self.data, accepted_media_type, context)
  File "/home/dverdun/.local/lib/python3.10/site-packages/rest_framework/renderers.py", line 723, in render
    context = self.get_context(data, accepted_media_type, renderer_context)
  File "/home/dverdun/.local/lib/python3.10/site-packages/rest_framework/renderers.py", line 654, in get_context
    raw_data_post_form = self.get_raw_data_form(data, view, 'POST', request)
  File "/home/dverdun/.local/lib/python3.10/site-packages/rest_framework/renderers.py", line 562, in get_raw_data_form
    data = serializer.data.copy()
  File "/home/dverdun/.local/lib/python3.10/site-packages/rest_framework/serializers.py", line 555, in data
    ret = super().data
  File "/home/dverdun/.local/lib/python3.10/site-packages/rest_framework/serializers.py", line 257, in data
    self._data = self.get_initial()
  File "/home/dverdun/.local/lib/python3.10/site-packages/rest_framework/serializers.py", line 405, in get_initial
    for field in self.fields.values()
  File "/home/dverdun/.local/lib/python3.10/site-packages/django/utils/functional.py", line 47, in __get__
    res = instance.__dict__[self.name] = self.func(instance)
  File "/home/dverdun/.local/lib/python3.10/site-packages/rest_framework/serializers.py", line 356, in fields
    for key, value in self.get_fields().items():
  File "/home/dverdun/.local/lib/python3.10/site-packages/rest_framework/serializers.py", line 1076, in get_fields
    field_class, field_kwargs = self.build_field(
  File "/home/dverdun/.local/lib/python3.10/site-packages/rest_framework/serializers.py", line 1222, in build_field
    return self.build_unknown_field(field_name, model_class)
  File "/home/dverdun/.local/lib/python3.10/site-packages/rest_framework/serializers.py", line 1340, in build_unknown_field
    raise ImproperlyConfigured(
django.core.exceptions.ImproperlyConfigured: Field name `email,` is not valid for model `User`.
2024-01-21 00:34:49,872 - Thread-6 (process_request_thread) - MainProcess - django.server - ERROR - "GET /users/create/ HTTP/1.1" 500 127316
2024-01-21 00:37:23,081 - MainThread - MainProcess - django.utils.autoreload - INFO - /home/dverdun/Documentos/Programacion_python/Prueba_tecnica/ToDo-Challenge-invera/todo-challenge/Core/users/models.py changed, reloading.
2024-01-21 00:37:23,885 - MainThread - MainProcess - django.utils.autoreload - INFO - Watching for file changes with StatReloader
2024-01-21 00:37:47,004 - MainThread - MainProcess - django.utils.autoreload - INFO - Watching for file changes with StatReloader
2024-01-21 00:37:53,091 - Thread-1 (process_request_thread) - MainProcess - django.request - ERROR - Internal Server Error: /users/create/
Traceback (most recent call last):
  File "/home/dverdun/.local/lib/python3.10/site-packages/django/core/handlers/exception.py", line 55, in inner
    response = get_response(request)
  File "/home/dverdun/.local/lib/python3.10/site-packages/django/core/handlers/base.py", line 220, in _get_response
    response = response.render()
  File "/home/dverdun/.local/lib/python3.10/site-packages/django/template/response.py", line 114, in render
    self.content = self.rendered_content
  File "/home/dverdun/.local/lib/python3.10/site-packages/rest_framework/response.py", line 70, in rendered_content
    ret = renderer.render(self.data, accepted_media_type, context)
  File "/home/dverdun/.local/lib/python3.10/site-packages/rest_framework/renderers.py", line 723, in render
    context = self.get_context(data, accepted_media_type, renderer_context)
  File "/home/dverdun/.local/lib/python3.10/site-packages/rest_framework/renderers.py", line 654, in get_context
    raw_data_post_form = self.get_raw_data_form(data, view, 'POST', request)
  File "/home/dverdun/.local/lib/python3.10/site-packages/rest_framework/renderers.py", line 562, in get_raw_data_form
    data = serializer.data.copy()
  File "/home/dverdun/.local/lib/python3.10/site-packages/rest_framework/serializers.py", line 555, in data
    ret = super().data
  File "/home/dverdun/.local/lib/python3.10/site-packages/rest_framework/serializers.py", line 257, in data
    self._data = self.get_initial()
  File "/home/dverdun/.local/lib/python3.10/site-packages/rest_framework/serializers.py", line 405, in get_initial
    for field in self.fields.values()
  File "/home/dverdun/.local/lib/python3.10/site-packages/django/utils/functional.py", line 47, in __get__
    res = instance.__dict__[self.name] = self.func(instance)
  File "/home/dverdun/.local/lib/python3.10/site-packages/rest_framework/serializers.py", line 356, in fields
    for key, value in self.get_fields().items():
  File "/home/dverdun/.local/lib/python3.10/site-packages/rest_framework/serializers.py", line 1076, in get_fields
    field_class, field_kwargs = self.build_field(
  File "/home/dverdun/.local/lib/python3.10/site-packages/rest_framework/serializers.py", line 1222, in build_field
    return self.build_unknown_field(field_name, model_class)
  File "/home/dverdun/.local/lib/python3.10/site-packages/rest_framework/serializers.py", line 1340, in build_unknown_field
    raise ImproperlyConfigured(
django.core.exceptions.ImproperlyConfigured: Field name `email,` is not valid for model `User`.
2024-01-21 00:37:53,095 - Thread-1 (process_request_thread) - MainProcess - django.server - ERROR - "GET /users/create/ HTTP/1.1" 500 127453
2024-01-21 00:47:27,477 - MainThread - MainProcess - django.utils.autoreload - INFO - /home/dverdun/Documentos/Programacion_python/Prueba_tecnica/ToDo-Challenge-invera/todo-challenge/Core/users/models.py changed, reloading.
2024-01-21 00:47:27,980 - MainThread - MainProcess - django.utils.autoreload - INFO - Watching for file changes with StatReloader
2024-01-21 00:47:41,992 - MainThread - MainProcess - django.utils.autoreload - INFO - Watching for file changes with StatReloader
2024-01-21 00:47:45,540 - Thread-1 (process_request_thread) - MainProcess - django.request - ERROR - Internal Server Error: /users/create/
Traceback (most recent call last):
  File "/home/dverdun/.local/lib/python3.10/site-packages/django/core/handlers/exception.py", line 55, in inner
    response = get_response(request)
  File "/home/dverdun/.local/lib/python3.10/site-packages/django/core/handlers/base.py", line 197, in _get_response
    response = wrapped_callback(request, *callback_args, **callback_kwargs)
  File "/home/dverdun/.local/lib/python3.10/site-packages/django/views/decorators/csrf.py", line 65, in _view_wrapper
    return view_func(request, *args, **kwargs)
  File "/home/dverdun/.local/lib/python3.10/site-packages/django/views/generic/base.py", line 104, in view
    return self.dispatch(request, *args, **kwargs)
  File "/home/dverdun/.local/lib/python3.10/site-packages/rest_framework/views.py", line 509, in dispatch
    response = self.handle_exception(exc)
  File "/home/dverdun/.local/lib/python3.10/site-packages/rest_framework/views.py", line 469, in handle_exception
    self.raise_uncaught_exception(exc)
  File "/home/dverdun/.local/lib/python3.10/site-packages/rest_framework/views.py", line 480, in raise_uncaught_exception
    raise exc
  File "/home/dverdun/.local/lib/python3.10/site-packages/rest_framework/views.py", line 506, in dispatch
    response = handler(request, *args, **kwargs)
  File "/home/dverdun/.local/lib/python3.10/site-packages/rest_framework/generics.py", line 190, in post
    return self.create(request, *args, **kwargs)
  File "/home/dverdun/.local/lib/python3.10/site-packages/rest_framework/mixins.py", line 18, in create
    serializer.is_valid(raise_exception=True)
  File "/home/dverdun/.local/lib/python3.10/site-packages/rest_framework/serializers.py", line 227, in is_valid
    self._validated_data = self.run_validation(self.initial_data)
  File "/home/dverdun/.local/lib/python3.10/site-packages/rest_framework/serializers.py", line 426, in run_validation
    value = self.to_internal_value(data)
  File "/home/dverdun/.local/lib/python3.10/site-packages/rest_framework/serializers.py", line 479, in to_internal_value
    for field in fields:
  File "/home/dverdun/.local/lib/python3.10/site-packages/rest_framework/serializers.py", line 362, in _writable_fields
    for field in self.fields.values():
  File "/home/dverdun/.local/lib/python3.10/site-packages/django/utils/functional.py", line 47, in __get__
    res = instance.__dict__[self.name] = self.func(instance)
  File "/home/dverdun/.local/lib/python3.10/site-packages/rest_framework/serializers.py", line 356, in fields
    for key, value in self.get_fields().items():
  File "/home/dverdun/.local/lib/python3.10/site-packages/rest_framework/serializers.py", line 1076, in get_fields
    field_class, field_kwargs = self.build_field(
  File "/home/dverdun/.local/lib/python3.10/site-packages/rest_framework/serializers.py", line 1222, in build_field
    return self.build_unknown_field(field_name, model_class)
  File "/home/dverdun/.local/lib/python3.10/site-packages/rest_framework/serializers.py", line 1340, in build_unknown_field
    raise ImproperlyConfigured(
django.core.exceptions.ImproperlyConfigured: Field name `email,` is not valid for model `User`.
2024-01-21 00:47:45,546 - Thread-1 (process_request_thread) - MainProcess - django.server - ERROR - "POST /users/create/ HTTP/1.1" 500 139212
2024-01-21 00:48:05,370 - Thread-2 (process_request_thread) - MainProcess - django.request - ERROR - Internal Server Error: /users/create/
Traceback (most recent call last):
  File "/home/dverdun/.local/lib/python3.10/site-packages/django/core/handlers/exception.py", line 55, in inner
    response = get_response(request)
  File "/home/dverdun/.local/lib/python3.10/site-packages/django/core/handlers/base.py", line 220, in _get_response
    response = response.render()
  File "/home/dverdun/.local/lib/python3.10/site-packages/django/template/response.py", line 114, in render
    self.content = self.rendered_content
  File "/home/dverdun/.local/lib/python3.10/site-packages/rest_framework/response.py", line 70, in rendered_content
    ret = renderer.render(self.data, accepted_media_type, context)
  File "/home/dverdun/.local/lib/python3.10/site-packages/rest_framework/renderers.py", line 723, in render
    context = self.get_context(data, accepted_media_type, renderer_context)
  File "/home/dverdun/.local/lib/python3.10/site-packages/rest_framework/renderers.py", line 654, in get_context
    raw_data_post_form = self.get_raw_data_form(data, view, 'POST', request)
  File "/home/dverdun/.local/lib/python3.10/site-packages/rest_framework/renderers.py", line 562, in get_raw_data_form
    data = serializer.data.copy()
  File "/home/dverdun/.local/lib/python3.10/site-packages/rest_framework/serializers.py", line 555, in data
    ret = super().data
  File "/home/dverdun/.local/lib/python3.10/site-packages/rest_framework/serializers.py", line 257, in data
    self._data = self.get_initial()
  File "/home/dverdun/.local/lib/python3.10/site-packages/rest_framework/serializers.py", line 405, in get_initial
    for field in self.fields.values()
  File "/home/dverdun/.local/lib/python3.10/site-packages/django/utils/functional.py", line 47, in __get__
    res = instance.__dict__[self.name] = self.func(instance)
  File "/home/dverdun/.local/lib/python3.10/site-packages/rest_framework/serializers.py", line 356, in fields
    for key, value in self.get_fields().items():
  File "/home/dverdun/.local/lib/python3.10/site-packages/rest_framework/serializers.py", line 1076, in get_fields
    field_class, field_kwargs = self.build_field(
  File "/home/dverdun/.local/lib/python3.10/site-packages/rest_framework/serializers.py", line 1222, in build_field
    return self.build_unknown_field(field_name, model_class)
  File "/home/dverdun/.local/lib/python3.10/site-packages/rest_framework/serializers.py", line 1340, in build_unknown_field
    raise ImproperlyConfigured(
django.core.exceptions.ImproperlyConfigured: Field name `email,` is not valid for model `User`.
2024-01-21 00:48:05,371 - Thread-2 (process_request_thread) - MainProcess - django.server - ERROR - "GET /users/create/ HTTP/1.1" 500 127453
2024-01-21 00:48:06,834 - Thread-2 (process_request_thread) - MainProcess - django.request - ERROR - Internal Server Error: /users/create/
Traceback (most recent call last):
  File "/home/dverdun/.local/lib/python3.10/site-packages/django/core/handlers/exception.py", line 55, in inner
    response = get_response(request)
  File "/home/dverdun/.local/lib/python3.10/site-packages/django/core/handlers/base.py", line 220, in _get_response
    response = response.render()
  File "/home/dverdun/.local/lib/python3.10/site-packages/django/template/response.py", line 114, in render
    self.content = self.rendered_content
  File "/home/dverdun/.local/lib/python3.10/site-packages/rest_framework/response.py", line 70, in rendered_content
    ret = renderer.render(self.data, accepted_media_type, context)
  File "/home/dverdun/.local/lib/python3.10/site-packages/rest_framework/renderers.py", line 723, in render
    context = self.get_context(data, accepted_media_type, renderer_context)
  File "/home/dverdun/.local/lib/python3.10/site-packages/rest_framework/renderers.py", line 654, in get_context
    raw_data_post_form = self.get_raw_data_form(data, view, 'POST', request)
  File "/home/dverdun/.local/lib/python3.10/site-packages/rest_framework/renderers.py", line 562, in get_raw_data_form
    data = serializer.data.copy()
  File "/home/dverdun/.local/lib/python3.10/site-packages/rest_framework/serializers.py", line 555, in data
    ret = super().data
  File "/home/dverdun/.local/lib/python3.10/site-packages/rest_framework/serializers.py", line 257, in data
    self._data = self.get_initial()
  File "/home/dverdun/.local/lib/python3.10/site-packages/rest_framework/serializers.py", line 405, in get_initial
    for field in self.fields.values()
  File "/home/dverdun/.local/lib/python3.10/site-packages/django/utils/functional.py", line 47, in __get__
    res = instance.__dict__[self.name] = self.func(instance)
  File "/home/dverdun/.local/lib/python3.10/site-packages/rest_framework/serializers.py", line 356, in fields
    for key, value in self.get_fields().items():
  File "/home/dverdun/.local/lib/python3.10/site-packages/rest_framework/serializers.py", line 1076, in get_fields
    field_class, field_kwargs = self.build_field(
  File "/home/dverdun/.local/lib/python3.10/site-packages/rest_framework/serializers.py", line 1222, in build_field
    return self.build_unknown_field(field_name, model_class)
  File "/home/dverdun/.local/lib/python3.10/site-packages/rest_framework/serializers.py", line 1340, in build_unknown_field
    raise ImproperlyConfigured(
django.core.exceptions.ImproperlyConfigured: Field name `email,` is not valid for model `User`.
2024-01-21 00:48:06,835 - Thread-2 (process_request_thread) - MainProcess - django.server - ERROR - "GET /users/create/ HTTP/1.1" 500 127453
2024-01-21 00:59:53,061 - MainThread - MainProcess - django.utils.autoreload - INFO - /home/dverdun/Documentos/Programacion_python/Prueba_tecnica/ToDo-Challenge-invera/todo-challenge/Core/users/serializers.py changed, reloading.
2024-01-21 00:59:53,796 - MainThread - MainProcess - django.utils.autoreload - INFO - Watching for file changes with StatReloader
2024-01-21 01:00:32,896 - MainThread - MainProcess - django.utils.autoreload - INFO - /home/dverdun/Documentos/Programacion_python/Prueba_tecnica/ToDo-Challenge-invera/todo-challenge/Core/users/views.py changed, reloading.
2024-01-21 01:00:33,608 - MainThread - MainProcess - django.utils.autoreload - INFO - Watching for file changes with StatReloader
2024-01-21 01:01:28,620 - Thread-1 (process_request_thread) - MainProcess - django.request - ERROR - Internal Server Error: /users/create/
Traceback (most recent call last):
  File "/home/dverdun/.local/lib/python3.10/site-packages/django/core/handlers/exception.py", line 55, in inner
    response = get_response(request)
  File "/home/dverdun/.local/lib/python3.10/site-packages/django/core/handlers/base.py", line 197, in _get_response
    response = wrapped_callback(request, *callback_args, **callback_kwargs)
  File "/home/dverdun/.local/lib/python3.10/site-packages/django/views/decorators/csrf.py", line 65, in _view_wrapper
    return view_func(request, *args, **kwargs)
  File "/home/dverdun/.local/lib/python3.10/site-packages/django/views/generic/base.py", line 104, in view
    return self.dispatch(request, *args, **kwargs)
  File "/home/dverdun/.local/lib/python3.10/site-packages/rest_framework/views.py", line 509, in dispatch
    response = self.handle_exception(exc)
  File "/home/dverdun/.local/lib/python3.10/site-packages/rest_framework/views.py", line 469, in handle_exception
    self.raise_uncaught_exception(exc)
  File "/home/dverdun/.local/lib/python3.10/site-packages/rest_framework/views.py", line 480, in raise_uncaught_exception
    raise exc
  File "/home/dverdun/.local/lib/python3.10/site-packages/rest_framework/views.py", line 506, in dispatch
    response = handler(request, *args, **kwargs)
  File "/home/dverdun/.local/lib/python3.10/site-packages/rest_framework/generics.py", line 190, in post
    return self.create(request, *args, **kwargs)
  File "/home/dverdun/.local/lib/python3.10/site-packages/rest_framework/mixins.py", line 18, in create
    serializer.is_valid(raise_exception=True)
  File "/home/dverdun/.local/lib/python3.10/site-packages/rest_framework/serializers.py", line 227, in is_valid
    self._validated_data = self.run_validation(self.initial_data)
  File "/home/dverdun/.local/lib/python3.10/site-packages/rest_framework/serializers.py", line 426, in run_validation
    value = self.to_internal_value(data)
  File "/home/dverdun/.local/lib/python3.10/site-packages/rest_framework/serializers.py", line 479, in to_internal_value
    for field in fields:
  File "/home/dverdun/.local/lib/python3.10/site-packages/rest_framework/serializers.py", line 362, in _writable_fields
    for field in self.fields.values():
  File "/home/dverdun/.local/lib/python3.10/site-packages/django/utils/functional.py", line 47, in __get__
    res = instance.__dict__[self.name] = self.func(instance)
  File "/home/dverdun/.local/lib/python3.10/site-packages/rest_framework/serializers.py", line 356, in fields
    for key, value in self.get_fields().items():
  File "/home/dverdun/.local/lib/python3.10/site-packages/rest_framework/serializers.py", line 1076, in get_fields
    field_class, field_kwargs = self.build_field(
  File "/home/dverdun/.local/lib/python3.10/site-packages/rest_framework/serializers.py", line 1222, in build_field
    return self.build_unknown_field(field_name, model_class)
  File "/home/dverdun/.local/lib/python3.10/site-packages/rest_framework/serializers.py", line 1340, in build_unknown_field
    raise ImproperlyConfigured(
django.core.exceptions.ImproperlyConfigured: Field name `email,` is not valid for model `User`.
2024-01-21 01:01:28,623 - Thread-1 (process_request_thread) - MainProcess - django.server - ERROR - "POST /users/create/ HTTP/1.1" 500 139212
2024-01-21 01:02:23,366 - MainThread - MainProcess - django.utils.autoreload - INFO - Watching for file changes with StatReloader
2024-01-21 01:02:32,688 - Thread-1 (process_request_thread) - MainProcess - django.request - WARNING - Not Found: /users/
2024-01-21 01:02:32,688 - Thread-1 (process_request_thread) - MainProcess - django.server - WARNING - "GET /users/ HTTP/1.1" 404 2679
2024-01-21 01:02:38,707 - Thread-1 (process_request_thread) - MainProcess - django.request - WARNING - Not Found: /
2024-01-21 01:02:38,709 - Thread-1 (process_request_thread) - MainProcess - django.server - WARNING - "GET / HTTP/1.1" 404 2272
2024-01-21 01:02:39,470 - Thread-1 (process_request_thread) - MainProcess - django.server - INFO - "GET /admin/ HTTP/1.1" 302 0
2024-01-21 01:02:39,523 - Thread-1 (process_request_thread) - MainProcess - django.server - INFO - "GET /admin/login/?next=/admin/ HTTP/1.1" 200 4155
2024-01-21 01:02:58,954 - Thread-1 (process_request_thread) - MainProcess - django.server - INFO - "POST /admin/login/?next=/admin/ HTTP/1.1" 302 0
2024-01-21 01:02:58,981 - Thread-1 (process_request_thread) - MainProcess - django.server - INFO - "GET /admin/ HTTP/1.1" 200 5773
2024-01-21 01:03:02,102 - Thread-1 (process_request_thread) - MainProcess - django.server - INFO - "GET /admin/users/user/ HTTP/1.1" 200 8402
2024-01-21 01:03:02,132 - Thread-1 (process_request_thread) - MainProcess - django.server - INFO - "GET /admin/jsi18n/ HTTP/1.1" 200 3342
2024-01-21 01:03:30,087 - Thread-3 (process_request_thread) - MainProcess - django.request - ERROR - Internal Server Error: /users/create/
Traceback (most recent call last):
  File "/home/dverdun/.local/lib/python3.10/site-packages/django/core/handlers/exception.py", line 55, in inner
    response = get_response(request)
  File "/home/dverdun/.local/lib/python3.10/site-packages/django/core/handlers/base.py", line 197, in _get_response
    response = wrapped_callback(request, *callback_args, **callback_kwargs)
  File "/home/dverdun/.local/lib/python3.10/site-packages/django/views/decorators/csrf.py", line 65, in _view_wrapper
    return view_func(request, *args, **kwargs)
  File "/home/dverdun/.local/lib/python3.10/site-packages/django/views/generic/base.py", line 104, in view
    return self.dispatch(request, *args, **kwargs)
  File "/home/dverdun/.local/lib/python3.10/site-packages/rest_framework/views.py", line 509, in dispatch
    response = self.handle_exception(exc)
  File "/home/dverdun/.local/lib/python3.10/site-packages/rest_framework/views.py", line 469, in handle_exception
    self.raise_uncaught_exception(exc)
  File "/home/dverdun/.local/lib/python3.10/site-packages/rest_framework/views.py", line 480, in raise_uncaught_exception
    raise exc
  File "/home/dverdun/.local/lib/python3.10/site-packages/rest_framework/views.py", line 506, in dispatch
    response = handler(request, *args, **kwargs)
  File "/home/dverdun/.local/lib/python3.10/site-packages/rest_framework/generics.py", line 190, in post
    return self.create(request, *args, **kwargs)
  File "/home/dverdun/.local/lib/python3.10/site-packages/rest_framework/mixins.py", line 18, in create
    serializer.is_valid(raise_exception=True)
  File "/home/dverdun/.local/lib/python3.10/site-packages/rest_framework/serializers.py", line 227, in is_valid
    self._validated_data = self.run_validation(self.initial_data)
  File "/home/dverdun/.local/lib/python3.10/site-packages/rest_framework/serializers.py", line 426, in run_validation
    value = self.to_internal_value(data)
  File "/home/dverdun/.local/lib/python3.10/site-packages/rest_framework/serializers.py", line 479, in to_internal_value
    for field in fields:
  File "/home/dverdun/.local/lib/python3.10/site-packages/rest_framework/serializers.py", line 362, in _writable_fields
    for field in self.fields.values():
  File "/home/dverdun/.local/lib/python3.10/site-packages/django/utils/functional.py", line 47, in __get__
    res = instance.__dict__[self.name] = self.func(instance)
  File "/home/dverdun/.local/lib/python3.10/site-packages/rest_framework/serializers.py", line 356, in fields
    for key, value in self.get_fields().items():
  File "/home/dverdun/.local/lib/python3.10/site-packages/rest_framework/serializers.py", line 1076, in get_fields
    field_class, field_kwargs = self.build_field(
  File "/home/dverdun/.local/lib/python3.10/site-packages/rest_framework/serializers.py", line 1222, in build_field
    return self.build_unknown_field(field_name, model_class)
  File "/home/dverdun/.local/lib/python3.10/site-packages/rest_framework/serializers.py", line 1340, in build_unknown_field
    raise ImproperlyConfigured(
django.core.exceptions.ImproperlyConfigured: Field name `email,` is not valid for model `User`.
2024-01-21 01:03:30,089 - Thread-3 (process_request_thread) - MainProcess - django.server - ERROR - "POST /users/create/ HTTP/1.1" 500 139212
2024-01-21 01:05:39,034 - MainThread - MainProcess - django.utils.autoreload - INFO - /home/dverdun/Documentos/Programacion_python/Prueba_tecnica/ToDo-Challenge-invera/todo-challenge/Core/users/models.py changed, reloading.
2024-01-21 01:05:39,564 - MainThread - MainProcess - django.utils.autoreload - INFO - Watching for file changes with StatReloader
2024-01-21 01:06:02,485 - Thread-1 (process_request_thread) - MainProcess - django.request - ERROR - Internal Server Error: /users/create/
Traceback (most recent call last):
  File "/home/dverdun/.local/lib/python3.10/site-packages/django/core/handlers/exception.py", line 55, in inner
    response = get_response(request)
  File "/home/dverdun/.local/lib/python3.10/site-packages/django/core/handlers/base.py", line 197, in _get_response
    response = wrapped_callback(request, *callback_args, **callback_kwargs)
  File "/home/dverdun/.local/lib/python3.10/site-packages/django/views/decorators/csrf.py", line 65, in _view_wrapper
    return view_func(request, *args, **kwargs)
  File "/home/dverdun/.local/lib/python3.10/site-packages/django/views/generic/base.py", line 104, in view
    return self.dispatch(request, *args, **kwargs)
  File "/home/dverdun/.local/lib/python3.10/site-packages/rest_framework/views.py", line 509, in dispatch
    response = self.handle_exception(exc)
  File "/home/dverdun/.local/lib/python3.10/site-packages/rest_framework/views.py", line 469, in handle_exception
    self.raise_uncaught_exception(exc)
  File "/home/dverdun/.local/lib/python3.10/site-packages/rest_framework/views.py", line 480, in raise_uncaught_exception
    raise exc
  File "/home/dverdun/.local/lib/python3.10/site-packages/rest_framework/views.py", line 506, in dispatch
    response = handler(request, *args, **kwargs)
  File "/home/dverdun/.local/lib/python3.10/site-packages/rest_framework/generics.py", line 190, in post
    return self.create(request, *args, **kwargs)
  File "/home/dverdun/.local/lib/python3.10/site-packages/rest_framework/mixins.py", line 18, in create
    serializer.is_valid(raise_exception=True)
  File "/home/dverdun/.local/lib/python3.10/site-packages/rest_framework/serializers.py", line 227, in is_valid
    self._validated_data = self.run_validation(self.initial_data)
  File "/home/dverdun/.local/lib/python3.10/site-packages/rest_framework/serializers.py", line 426, in run_validation
    value = self.to_internal_value(data)
  File "/home/dverdun/.local/lib/python3.10/site-packages/rest_framework/serializers.py", line 479, in to_internal_value
    for field in fields:
  File "/home/dverdun/.local/lib/python3.10/site-packages/rest_framework/serializers.py", line 362, in _writable_fields
    for field in self.fields.values():
  File "/home/dverdun/.local/lib/python3.10/site-packages/django/utils/functional.py", line 47, in __get__
    res = instance.__dict__[self.name] = self.func(instance)
  File "/home/dverdun/.local/lib/python3.10/site-packages/rest_framework/serializers.py", line 356, in fields
    for key, value in self.get_fields().items():
  File "/home/dverdun/.local/lib/python3.10/site-packages/rest_framework/serializers.py", line 1076, in get_fields
    field_class, field_kwargs = self.build_field(
  File "/home/dverdun/.local/lib/python3.10/site-packages/rest_framework/serializers.py", line 1222, in build_field
    return self.build_unknown_field(field_name, model_class)
  File "/home/dverdun/.local/lib/python3.10/site-packages/rest_framework/serializers.py", line 1340, in build_unknown_field
    raise ImproperlyConfigured(
django.core.exceptions.ImproperlyConfigured: Field name `email,` is not valid for model `User`.
2024-01-21 01:06:02,487 - Thread-1 (process_request_thread) - MainProcess - django.server - ERROR - "POST /users/create/ HTTP/1.1" 500 139212
2024-01-21 01:06:17,823 - Thread-1 (process_request_thread) - MainProcess - django.request - WARNING - Unauthorized: /users/user/
2024-01-21 01:06:17,824 - Thread-1 (process_request_thread) - MainProcess - django.server - WARNING - "POST /users/user/ HTTP/1.1" 401 58
2024-01-21 01:07:39,981 - MainThread - MainProcess - django.utils.autoreload - INFO - /home/dverdun/Documentos/Programacion_python/Prueba_tecnica/ToDo-Challenge-invera/todo-challenge/Core/users/serializers.py changed, reloading.
2024-01-21 01:07:40,482 - MainThread - MainProcess - django.utils.autoreload - INFO - Watching for file changes with StatReloader
2024-01-21 01:07:53,352 - Thread-1 (process_request_thread) - MainProcess - django.server - INFO - "POST /users/create/ HTTP/1.1" 201 46
2024-01-21 01:13:18,758 - Thread-1 (process_request_thread) - MainProcess - django.request - WARNING - Bad Request: /users/token/
2024-01-21 01:13:18,759 - Thread-1 (process_request_thread) - MainProcess - django.server - WARNING - "POST /users/token/ HTTP/1.1" 400 73
2024-01-21 01:13:27,307 - Thread-1 (process_request_thread) - MainProcess - django.request - WARNING - Bad Request: /users/token/
2024-01-21 01:13:27,308 - Thread-1 (process_request_thread) - MainProcess - django.server - WARNING - "POST /users/token/ HTTP/1.1" 400 76
2024-01-21 01:16:42,389 - Thread-1 (process_request_thread) - MainProcess - django.request - ERROR - Internal Server Error: /users/token/
Traceback (most recent call last):
  File "/home/dverdun/.local/lib/python3.10/site-packages/django/core/handlers/exception.py", line 55, in inner
    response = get_response(request)
  File "/home/dverdun/.local/lib/python3.10/site-packages/django/core/handlers/base.py", line 197, in _get_response
    response = wrapped_callback(request, *callback_args, **callback_kwargs)
  File "/home/dverdun/.local/lib/python3.10/site-packages/django/views/decorators/csrf.py", line 65, in _view_wrapper
    return view_func(request, *args, **kwargs)
  File "/home/dverdun/.local/lib/python3.10/site-packages/django/views/generic/base.py", line 104, in view
    return self.dispatch(request, *args, **kwargs)
  File "/home/dverdun/.local/lib/python3.10/site-packages/rest_framework/views.py", line 509, in dispatch
    response = self.handle_exception(exc)
  File "/home/dverdun/.local/lib/python3.10/site-packages/rest_framework/views.py", line 469, in handle_exception
    self.raise_uncaught_exception(exc)
  File "/home/dverdun/.local/lib/python3.10/site-packages/rest_framework/views.py", line 480, in raise_uncaught_exception
    raise exc
  File "/home/dverdun/.local/lib/python3.10/site-packages/rest_framework/views.py", line 506, in dispatch
    response = handler(request, *args, **kwargs)
  File "/home/dverdun/.local/lib/python3.10/site-packages/rest_framework/authtoken/views.py", line 58, in post
    token, created = Token.objects.get_or_create(user=user)
AttributeError: type object 'Token' has no attribute 'objects'
2024-01-21 01:16:42,390 - Thread-1 (process_request_thread) - MainProcess - django.server - ERROR - "POST /users/token/ HTTP/1.1" 500 90796
2024-01-21 02:19:34,245 - MainThread - MainProcess - django.utils.autoreload - INFO - /home/dverdun/Documentos/Programacion_python/Prueba_tecnica/ToDo-Challenge-invera/todo-challenge/Core/Core/settings.py changed, reloading.
2024-01-21 02:19:34,739 - MainThread - MainProcess - django.utils.autoreload - INFO - Watching for file changes with StatReloader
2024-01-21 02:19:40,073 - Thread-1 (process_request_thread) - MainProcess - django.request - ERROR - Internal Server Error: /users/token/
Traceback (most recent call last):
  File "/home/dverdun/.local/lib/python3.10/site-packages/django/db/backends/utils.py", line 105, in _execute
    return self.cursor.execute(sql, params)
  File "/home/dverdun/.local/lib/python3.10/site-packages/django/db/backends/sqlite3/base.py", line 328, in execute
    return super().execute(query, params)
sqlite3.OperationalError: no such table: authtoken_token

The above exception was the direct cause of the following exception:

Traceback (most recent call last):
  File "/home/dverdun/.local/lib/python3.10/site-packages/django/core/handlers/exception.py", line 55, in inner
    response = get_response(request)
  File "/home/dverdun/.local/lib/python3.10/site-packages/django/core/handlers/base.py", line 197, in _get_response
    response = wrapped_callback(request, *callback_args, **callback_kwargs)
  File "/home/dverdun/.local/lib/python3.10/site-packages/django/views/decorators/csrf.py", line 65, in _view_wrapper
    return view_func(request, *args, **kwargs)
  File "/home/dverdun/.local/lib/python3.10/site-packages/django/views/generic/base.py", line 104, in view
    return self.dispatch(request, *args, **kwargs)
  File "/home/dverdun/.local/lib/python3.10/site-packages/rest_framework/views.py", line 509, in dispatch
    response = self.handle_exception(exc)
  File "/home/dverdun/.local/lib/python3.10/site-packages/rest_framework/views.py", line 469, in handle_exception
    self.raise_uncaught_exception(exc)
  File "/home/dverdun/.local/lib/python3.10/site-packages/rest_framework/views.py", line 480, in raise_uncaught_exception
    raise exc
  File "/home/dverdun/.local/lib/python3.10/site-packages/rest_framework/views.py", line 506, in dispatch
    response = handler(request, *args, **kwargs)
  File "/home/dverdun/.local/lib/python3.10/site-packages/rest_framework/authtoken/views.py", line 58, in post
    token, created = Token.objects.get_or_create(user=user)
  File "/home/dverdun/.local/lib/python3.10/site-packages/django/db/models/manager.py", line 87, in manager_method
    return getattr(self.get_queryset(), name)(*args, **kwargs)
  File "/home/dverdun/.local/lib/python3.10/site-packages/django/db/models/query.py", line 946, in get_or_create
    return self.get(**kwargs), False
  File "/home/dverdun/.local/lib/python3.10/site-packages/django/db/models/query.py", line 643, in get
    num = len(clone)
  File "/home/dverdun/.local/lib/python3.10/site-packages/django/db/models/query.py", line 380, in __len__
    self._fetch_all()
  File "/home/dverdun/.local/lib/python3.10/site-packages/django/db/models/query.py", line 1926, in _fetch_all
    self._result_cache = list(self._iterable_class(self))
  File "/home/dverdun/.local/lib/python3.10/site-packages/django/db/models/query.py", line 91, in __iter__
    results = compiler.execute_sql(
  File "/home/dverdun/.local/lib/python3.10/site-packages/django/db/models/sql/compiler.py", line 1562, in execute_sql
    cursor.execute(sql, params)
  File "/home/dverdun/.local/lib/python3.10/site-packages/django/db/backends/utils.py", line 122, in execute
    return super().execute(sql, params)
  File "/home/dverdun/.local/lib/python3.10/site-packages/django/db/backends/utils.py", line 79, in execute
    return self._execute_with_wrappers(
  File "/home/dverdun/.local/lib/python3.10/site-packages/django/db/backends/utils.py", line 92, in _execute_with_wrappers
    return executor(sql, params, many, context)
  File "/home/dverdun/.local/lib/python3.10/site-packages/django/db/backends/utils.py", line 100, in _execute
    with self.db.wrap_database_errors:
  File "/home/dverdun/.local/lib/python3.10/site-packages/django/db/utils.py", line 91, in __exit__
    raise dj_exc_value.with_traceback(traceback) from exc_value
  File "/home/dverdun/.local/lib/python3.10/site-packages/django/db/backends/utils.py", line 105, in _execute
    return self.cursor.execute(sql, params)
  File "/home/dverdun/.local/lib/python3.10/site-packages/django/db/backends/sqlite3/base.py", line 328, in execute
    return super().execute(query, params)
django.db.utils.OperationalError: no such table: authtoken_token
2024-01-21 02:19:40,075 - Thread-1 (process_request_thread) - MainProcess - django.server - ERROR - "POST /users/token/ HTTP/1.1" 500 164038
2024-01-21 02:20:13,575 - MainThread - MainProcess - django.utils.autoreload - INFO - Watching for file changes with StatReloader
2024-01-21 02:20:50,906 - Thread-1 (process_request_thread) - MainProcess - django.server - INFO - "POST /users/token/ HTTP/1.1" 200 52
2024-01-21 02:23:51,346 - Thread-1 (process_request_thread) - MainProcess - django.server - INFO - "GET /api/v1.0/tasks/ HTTP/1.1" 200 2
2024-01-21 02:26:08,194 - Thread-2 (process_request_thread) - MainProcess - django.request - WARNING - Unauthorized: /api/v1.0/tasks/
2024-01-21 02:26:08,195 - Thread-2 (process_request_thread) - MainProcess - django.server - WARNING - "GET /api/v1.0/tasks/ HTTP/1.1" 401 5086
2024-01-21 02:27:49,628 - Thread-1 (process_request_thread) - MainProcess - django.request - WARNING - Unauthorized: /api/v1.0/tasks/
2024-01-21 02:27:49,628 - Thread-1 (process_request_thread) - MainProcess - django.server - WARNING - "POST /api/v1.0/tasks/ HTTP/1.1" 401 58
2024-01-21 10:58:45,900 - MainThread - MainProcess - django.utils.autoreload - INFO - Watching for file changes with StatReloader
2024-01-21 10:59:30,776 - Thread-1 (process_request_thread) - MainProcess - django.request - WARNING - Not Found: /
2024-01-21 10:59:30,776 - Thread-1 (process_request_thread) - MainProcess - django.server - WARNING - "GET / HTTP/1.1" 404 2289
2024-01-21 10:59:31,870 - Thread-1 (process_request_thread) - MainProcess - django.request - WARNING - Not Found: /
2024-01-21 10:59:31,871 - Thread-1 (process_request_thread) - MainProcess - django.server - WARNING - "GET / HTTP/1.1" 404 2289
2024-01-21 10:59:45,075 - Thread-1 (process_request_thread) - MainProcess - django.request - WARNING - Not Found: /api/v1.0/authentication
2024-01-21 10:59:45,076 - Thread-1 (process_request_thread) - MainProcess - django.server - WARNING - "GET /api/v1.0/authentication HTTP/1.1" 404 3059
2024-01-21 11:00:17,174 - Thread-1 (process_request_thread) - MainProcess - django.request - WARNING - Not Found: /api/v1.0/authentication/create
2024-01-21 11:00:17,176 - Thread-1 (process_request_thread) - MainProcess - django.server - WARNING - "GET /api/v1.0/authentication/create HTTP/1.1" 404 3080
2024-01-21 11:00:56,779 - Thread-3 (process_request_thread) - MainProcess - django.request - WARNING - Not Found: /api/v1.0/authentication/create
2024-01-21 11:00:56,780 - Thread-3 (process_request_thread) - MainProcess - django.server - WARNING - "POST /api/v1.0/authentication/create HTTP/1.1" 404 3081
2024-01-21 11:01:28,880 - MainThread - MainProcess - django.utils.autoreload - INFO - /home/dverdun/Documentos/Programacion_python/Prueba_tecnica/ToDo-Challenge-invera/todo-challenge/Core/Core/urls.py changed, reloading.
2024-01-21 11:01:29,603 - MainThread - MainProcess - django.utils.autoreload - INFO - Watching for file changes with StatReloader
2024-01-21 11:01:35,125 - Thread-1 (process_request_thread) - MainProcess - django.server - INFO - "GET /api/v1.0/authentication/create HTTP/1.1" 301 0
2024-01-21 11:01:35,171 - Thread-2 (process_request_thread) - MainProcess - django.request - WARNING - Method Not Allowed: /api/v1.0/authentication/create/
2024-01-21 11:01:35,172 - Thread-2 (process_request_thread) - MainProcess - django.server - WARNING - "GET /api/v1.0/authentication/create/ HTTP/1.1" 405 7877
2024-01-21 11:01:35,196 - Thread-2 (process_request_thread) - MainProcess - django.server - INFO - "GET /static/rest_framework/css/bootstrap.min.css HTTP/1.1" 304 0
2024-01-21 11:01:35,198 - Thread-3 (process_request_thread) - MainProcess - django.server - INFO - "GET /static/rest_framework/css/bootstrap-tweaks.css HTTP/1.1" 304 0
2024-01-21 11:01:35,199 - Thread-4 (process_request_thread) - MainProcess - django.server - INFO - "GET /static/rest_framework/css/prettify.css HTTP/1.1" 304 0
2024-01-21 11:01:35,205 - Thread-5 (process_request_thread) - MainProcess - django.server - INFO - "GET /static/rest_framework/css/default.css HTTP/1.1" 304 0
2024-01-21 11:01:35,208 - Thread-3 (process_request_thread) - MainProcess - django.server - INFO - "GET /static/rest_framework/js/csrf.js HTTP/1.1" 304 0
2024-01-21 11:01:35,210 - Thread-4 (process_request_thread) - MainProcess - django.server - INFO - "GET /static/rest_framework/js/bootstrap.min.js HTTP/1.1" 304 0
2024-01-21 11:01:35,210 - Thread-6 (process_request_thread) - MainProcess - django.server - INFO - "GET /static/rest_framework/js/jquery-3.5.1.min.js HTTP/1.1" 304 0
2024-01-21 11:01:35,210 - Thread-7 (process_request_thread) - MainProcess - django.server - INFO - "GET /static/rest_framework/js/ajax-form.js HTTP/1.1" 304 0
2024-01-21 11:01:35,210 - Thread-5 (process_request_thread) - MainProcess - django.server - INFO - "GET /static/rest_framework/js/prettify-min.js HTTP/1.1" 304 0
2024-01-21 11:01:35,213 - Thread-7 (process_request_thread) - MainProcess - django.server - INFO - "GET /static/rest_framework/js/default.js HTTP/1.1" 304 0
2024-01-21 11:01:35,277 - Thread-7 (process_request_thread) - MainProcess - django.server - INFO - "GET /static/rest_framework/img/grid.png HTTP/1.1" 304 0
2024-01-21 11:03:20,605 - Thread-7 (process_request_thread) - MainProcess - django.request - WARNING - Method Not Allowed: /api/v1.0/authentication/token/
2024-01-21 11:03:20,606 - Thread-7 (process_request_thread) - MainProcess - django.server - WARNING - "GET /api/v1.0/authentication/token/ HTTP/1.1" 405 40
2024-01-21 11:04:34,682 - Thread-8 (process_request_thread) - MainProcess - django.request - ERROR - Internal Server Error: /api/v1.0/authentication/token
Traceback (most recent call last):
  File "/home/dverdun/.local/lib/python3.10/site-packages/django/core/handlers/exception.py", line 55, in inner
    response = get_response(request)
  File "/home/dverdun/.local/lib/python3.10/site-packages/django/utils/deprecation.py", line 136, in __call__
    response = self.process_response(request, response)
  File "/home/dverdun/.local/lib/python3.10/site-packages/django/middleware/common.py", line 108, in process_response
    return self.response_redirect_class(self.get_full_path_with_slash(request))
  File "/home/dverdun/.local/lib/python3.10/site-packages/django/middleware/common.py", line 87, in get_full_path_with_slash
    raise RuntimeError(
RuntimeError: You called this URL via POST, but the URL doesn't end in a slash and you have APPEND_SLASH set. Django can't redirect to the slash URL while maintaining POST data. Change your form to point to 127.0.0.1:8000/api/v1.0/authentication/token/ (note the trailing slash), or set APPEND_SLASH=False in your Django settings.
2024-01-21 11:04:34,683 - Thread-8 (process_request_thread) - MainProcess - django.server - ERROR - "POST /api/v1.0/authentication/token HTTP/1.1" 500 68570
2024-01-21 11:04:38,700 - Thread-9 (process_request_thread) - MainProcess - django.request - WARNING - Bad Request: /api/v1.0/authentication/token/
2024-01-21 11:04:38,700 - Thread-9 (process_request_thread) - MainProcess - django.server - WARNING - "POST /api/v1.0/authentication/token/ HTTP/1.1" 400 76
2024-01-21 11:08:33,414 - Thread-9 (process_request_thread) - MainProcess - django.server - INFO - "POST /api/v1.0/authentication/token/ HTTP/1.1" 200 52
2024-01-21 11:09:52,736 - Thread-9 (process_request_thread) - MainProcess - django.request - WARNING - Unauthorized: /api/v1.0/tasks/
2024-01-21 11:09:52,737 - Thread-9 (process_request_thread) - MainProcess - django.server - WARNING - "GET /api/v1.0/tasks/ HTTP/1.1" 401 58
2024-01-21 11:13:46,890 - Thread-9 (process_request_thread) - MainProcess - django.server - INFO - "GET /api/v1.0/tasks/ HTTP/1.1" 200 2
2024-01-21 11:16:02,839 - Thread-9 (process_request_thread) - MainProcess - django.server - INFO - "POST /api/v1.0/tasks/ HTTP/1.1" 201 129
2024-01-21 11:17:09,774 - Thread-9 (process_request_thread) - MainProcess - django.server - INFO - "POST /api/v1.0/tasks/ HTTP/1.1" 201 129
2024-01-21 11:18:32,354 - Thread-9 (process_request_thread) - MainProcess - django.request - ERROR - Internal Server Error: /api/v1.0/tasks/2
Traceback (most recent call last):
  File "/home/dverdun/.local/lib/python3.10/site-packages/django/core/handlers/exception.py", line 55, in inner
    response = get_response(request)
  File "/home/dverdun/.local/lib/python3.10/site-packages/django/utils/deprecation.py", line 136, in __call__
    response = self.process_response(request, response)
  File "/home/dverdun/.local/lib/python3.10/site-packages/django/middleware/common.py", line 108, in process_response
    return self.response_redirect_class(self.get_full_path_with_slash(request))
  File "/home/dverdun/.local/lib/python3.10/site-packages/django/middleware/common.py", line 87, in get_full_path_with_slash
    raise RuntimeError(
RuntimeError: You called this URL via PUT, but the URL doesn't end in a slash and you have APPEND_SLASH set. Django can't redirect to the slash URL while maintaining PUT data. Change your form to point to 127.0.0.1:8000/api/v1.0/tasks/2/ (note the trailing slash), or set APPEND_SLASH=False in your Django settings.
2024-01-21 11:18:32,355 - Thread-9 (process_request_thread) - MainProcess - django.server - ERROR - "PUT /api/v1.0/tasks/2 HTTP/1.1" 500 68528
2024-01-21 11:18:48,930 - Thread-10 (process_request_thread) - MainProcess - django.server - INFO - "GET /api/v1.0/tasks/ HTTP/1.1" 200 261
2024-01-21 11:19:10,810 - Thread-10 (process_request_thread) - MainProcess - django.server - INFO - "GET /api/v1.0/tasks/2/ HTTP/1.1" 200 129
2024-01-21 11:19:15,658 - Thread-10 (process_request_thread) - MainProcess - django.server - INFO - "PUT /api/v1.0/tasks/2/ HTTP/1.1" 200 130
2024-01-21 11:20:27,983 - Thread-11 (process_request_thread) - MainProcess - django.request - WARNING - Unauthorized: /api/v1.0/tasks/
2024-01-21 11:20:27,984 - Thread-11 (process_request_thread) - MainProcess - django.server - WARNING - "GET /api/v1.0/tasks/ HTTP/1.1" 401 5086
2024-01-21 11:37:00,741 - MainThread - MainProcess - django.utils.autoreload - INFO - Watching for file changes with StatReloader
2024-01-21 11:38:17,410 - MainThread - MainProcess - django.utils.autoreload - INFO - /home/dverdun/Documentos/Programacion_python/Prueba_tecnica/ToDo-Challenge-invera/todo-challenge/Core/Core/settings.py changed, reloading.
2024-01-21 11:38:17,926 - MainThread - MainProcess - django.utils.autoreload - INFO - Watching for file changes with StatReloader
2024-01-21 11:48:27,158 - MainThread - MainProcess - django.utils.autoreload - INFO - Watching for file changes with StatReloader
2024-01-21 11:48:33,811 - Thread-1 (process_request_thread) - MainProcess - django.server - INFO - "POST /api/v1.0/tasks/ HTTP/1.1" 201 130
